File: export_angle_-5_330deg_2p1K_2000oe.dat
Time Stamp (sec),Temperature (K),Magnetic Field (Oe),Sample Position (degrees),Bridge 1 Resistance (Ohms)
1006829.718,2.09866396903992,1999.85548828125,-5.00444316864014,0.0429080954194069
1006849.812,2.09890055656433,1999.84481445313,-2.00577354431152,0.0410709550976753
1006869.687,2.09908429145813,1999.85982421875,0.986247301101685,0.0392348280549049
1006889.875,2.09901955604553,1999.83319335937,3.97826814651489,0.0378149108588696
1006910.109,2.09163535118103,1999.8458203125,6.97028923034668,0.035734536126256
1006931.671,2.09890670776367,1999.84290039062,9.95566177368164,0.03482362896204
1006951.687,2.09946650505066,1999.83952148437,12.9476833343506,0.0329891300201416
1006971.531,2.09930620193481,1999.83418945313,15.9397048950195,0.0321402470767498
1006991.312,2.10213934898376,1999.8288671875,18.9317264556885,0.0322433114051819
1007012.281,2.1020913028717,1999.77272460938,21.9237480163574,0.0317871376127005
1007032.171,2.09921441078186,1999.74948242188,24.9157695770264,0.0317952940613031
1007051.937,2.0992458820343,1999.82354492188,27.9077911376953,0.0325034086406231
1007072.234,2.09918097496033,1999.8264453125,30.8931636810303,0.0334440450370312
1007091.906,2.09922095298767,1999.80515625,33.8851852416992,0.0346155774593353
1007111.5,2.099304895401,1999.80564453125,36.8772087097168,0.036713725477457
1007131.546,2.09195515632629,1999.80322265625,39.8692321777344,0.0384292966127396
1007153.921,2.09994410514832,1999.81098632813,42.861255645752,0.0413068601489067
1007173.921,2.0998602771759,1999.825,45.8532791137695,0.0432811659574509
1007193.656,2.0996889591217,1999.82838867188,48.8453025817871,0.0447545218467712
1007213.703,2.10184432983398,1999.80948242187,51.8306770324707,0.0481936429440975
1007233.406,2.10145832061768,1999.82403320313,54.8227005004883,0.0504838635027409
1007253.609,2.09956148147583,1999.81920898438,57.8147239685059,0.0522063095867634
1007273.312,2.09958168029785,1999.81047851562,60.8067474365234,0.0535421355068684
1007293.265,2.09969841957092,1999.8211328125,63.798770904541,0.055079408288002
1007313.093,2.09950932502747,1999.82403320313,66.7907943725586,0.0560586299002171
1007333.75,2.09950295448303,1999.82693359375,69.7828216552734,0.0565487067401409
1007354.031,2.09164596557617,1999.82645507813,72.768196105957,0.0554850873351097
1007376.078,2.09958338737488,1999.82645507813,75.7602233886719,0.0567942133545876
1007395.921,2.10011267662048,1999.79307617188,78.7522506713867,0.0571446250379086
1007415.843,2.09985632896423,1999.81581054687,81.7442779541016,0.0576646821200848
1007436.062,2.10494647026062,1999.80275390625,84.7363052368164,0.0598235189914703
1007455.906,2.10201872825623,1999.79063476563,87.7283325195313,0.0589359351992607
1007475.718,2.09955856323242,1999.80227539063,90.7203598022461,0.0596356818079948
1007495.515,2.09963926315308,1999.8046875,93.7057342529297,0.0603439110517502
1007515.687,2.09968587875366,1999.8046875,96.6977615356445,0.0611103221774101
1007535.89,2.09969896316528,1999.80419921875,99.6897888183594,0.0619944037497044
1007555.687,2.09968082427979,1999.79061523438,102.681816101074,0.0629142923653126
1007576.5,2.09032920837402,1999.79934570313,105.673843383789,0.0626903359591961
1007597.953,2.09999853134155,1999.812421875,108.665870666504,0.0646771650016308
1007618,2.10038661956787,1999.78240234375,111.657897949219,0.0660856428742409
1007637.765,2.10033159255981,1999.80080078125,114.643272399902,0.0672620257735252
1007657.64,2.107135887146,1999.79935546875,117.635299682617,0.0694804367423058
1007677.968,2.10133702278137,1999.817265625,120.627326965332,0.068338515162468
1007698.14,2.09938230514526,1999.83272460938,123.619354248047,0.0688112702965736
1007717.828,2.09968933105469,1999.81821289063,126.611381530762,0.0687725561857224
1007737.75,2.09953969955444,1999.8066015625,129.603408813477,0.0683278721570969
1007757.796,2.09956085205078,1999.79984375,132.595443725586,0.0680409297347069
1007777.562,2.09994973182678,1999.80419921875,135.580825805664,0.0671445262432098
1007798,2.09120623588562,1999.81336914062,138.572860717773,0.0650089436769486
1007819.375,2.10010059356689,1999.81434570312,141.564895629883,0.0644187563657761
1007839.39,2.10034944534302,1999.79208984375,144.556930541992,0.0628905571997166
1007859.343,2.10053714752197,1999.78967773437,147.548965454102,0.0611788232624531
1007880.093,2.10841099739075,1999.79791992188,150.541000366211,0.0608056841790676
1007900.125,2.0989594745636,1999.81002929688,153.53303527832,0.0580355858802795
1007920,2.10038765907288,1999.78625976562,156.518417358398,0.0565549965202808
1007940.218,2.09989119529724,1999.8008203125,159.510452270508,0.0552676999568939
1007960.562,2.09980164527893,1999.76981445313,162.502487182617,0.0531191059947014
1007980.703,2.09993320465088,1999.74896972656,165.494522094727,0.0513257630169392
1008000.921,2.09996421813965,1999.79404296875,168.486557006836,0.0493233427405357
1008021.078,2.10570439338684,1999.80177734375,171.478591918945,0.0473290994763374
1008041.843,2.09938405036926,1999.7911328125,174.470626831055,0.0450503557920456
1008061.859,2.100785779953,1999.79743164063,177.456008911133,0.0431859560310841
1008081.687,2.10129373550415,1999.79645507813,180.448043823242,0.0410162198543549
1008101.968,2.10812536239624,1999.80854492188,183.440078735352,0.0403258554637432
1008121.781,2.10075817108154,1999.80662109375,186.432113647461,0.0370341530442238
1008141.421,2.09994943618774,1999.7993359375,189.42414855957,0.0355433776974678
1008161.5,2.10007436752319,1999.81,192.41618347168,0.0333593368530273
1008181.359,2.09997443199158,1999.8090234375,195.408218383789,0.0319441431760788
1008201.156,2.10011052131653,1999.80905273438,198.393600463867,0.0313061102479696
1008221.046,2.098518409729,1999.80516601563,201.385635375977,0.0306450086832047
1008241.25,2.09662734985352,1999.81484375,204.377670288086,0.0311400792002678
1008261.562,2.10091763496399,1999.79305664063,207.369705200195,0.0314210770279169
1008281.281,2.1011350440979,1999.84192382812,210.361740112305,0.0327838669717312
1008301,2.10112914085388,1999.84918945313,213.353775024414,0.0340019388496876
1008321.203,2.10741106033325,1999.83030273438,216.345809936523,0.0364110805094242
1008341.156,2.10070954322815,1999.84046875,219.331192016602,0.0375707310438156
1008361.125,2.09977272987366,1999.8308203125,222.323226928711,0.0397521257400513
1008381.718,2.09934453964233,1999.82887695313,225.31526184082,0.0415396718680859
1008401.562,2.10003195762634,1999.812890625,228.30729675293,0.0435022699832916
1008421.515,2.09990837097168,1999.82549804688,231.299331665039,0.045254240334034
1008441.687,2.09945343017578,1999.81578125,234.291366577148,0.0478024107217789
1008461.89,2.09648789405823,1999.80857421875,237.283401489258,0.049631207883358
1008482.812,2.10103309631348,1999.81626953125,240.268783569336,0.0529555486142635
1008502.468,2.10072341918945,1999.81868164063,243.260818481445,0.0539629372954369
1008522.328,2.10152482032776,1999.81432617188,246.252853393555,0.0553052420914173
1008542.671,2.10941313743591,1999.83369140625,249.244888305664,0.0572734102606773
1008562.25,2.10021571159363,1999.94461425781,252.236923217773,0.0557099701464176
1008581.937,2.10057269096375,1999.871953125,255.228958129883,0.0562790189683437
1008602.312,2.09955693244934,1999.83466796875,258.21435546875,0.0558236914873123
1008622.156,2.100059633255,1999.82450195313,261.206390380859,0.0564132654666901
1008642.14,2.09974013328552,1999.82209960938,264.198425292969,0.056643433868885
1008661.843,2.09473057746887,1999.80661132813,267.190460205078,0.0555214783549309
1008682.093,2.09572435379028,1999.81916992188,270.182495117188,0.0575848762691021
1008702.468,2.09996032714844,1999.81287109375,273.174530029297,0.0588430571556091
1008722.375,2.09991220474243,1999.80807617188,276.166564941406,0.0597119002044201
1008742.421,2.10084849357605,1999.81822265625,279.151947021484,0.060935555100441
1008762.64,2.10538261413574,1999.81387695312,282.143981933594,0.0620463168621063
1008782.64,2.1003493976593,1999.82643554688,285.136016845703,0.0627933369576931
1008802.203,2.09969957351685,1999.82209960938,288.128051757813,0.0629549627006054
1008823.109,2.09924214363098,1999.81677734375,291.120086669922,0.0634726566076279
1008843.046,2.1008632850647,1999.81048828125,294.112121582031,0.0643053451180458
1008862.89,2.10046817779541,1999.79888671875,297.104156494141,0.0654490119218826
1008883.015,2.09291565895081,1999.8216015625,300.089538574219,0.0653187610208988
1008903.875,2.1033175945282,1999.84873046875,303.081573486328,0.0674538633227348
1008923.64,2.1010280418396,1999.83321289063,306.073608398438,0.0670667526125908
1008943.718,2.10121560096741,1999.84919921875,309.065643310547,0.0668569800257683
1008963.578,2.10132462501526,1999.83563476562,312.057678222656,0.0664528775215149
1008983.796,2.09658916473389,1999.8341796875,315.049713134766,0.0650843837857246
1009003.609,2.09989743232727,1999.842421875,318.041748046875,0.0648985016345978
1009023.328,2.10046245574951,1999.82497070313,321.027130126953,0.064315467774868
1009043.031,2.10044032096863,1999.84435546875,324.019165039063,0.0633088810741901
1009062.859,2.10040616989136,1999.82305664063,327.011199951172,0.0623594163358212
1009082.734,2.10061019897461,1999.82643554688,330.003234863281,0.0611094066500664