File: export_0T_2T_angle_0_330deg_2K.dat
Time Stamp (sec),Temperature (K),Magnetic Field (Oe),Sample Position (degrees),Bridge 1 Resistance (Ohms)
1079498.625,1.99619610309601,573.449476318359,0.00219333171844482,0.01272196713835
1079536.265,1.99659217357636,2457.21405273437,0.00219333171844482,0.0380295321345329
1079573.531,1.9970001411438,4315.16421875,0.00219333171844482,0.0818955710530281
1079610.453,1.99726628303528,6169.01189453125,0.00219333171844482,0.116937426924706
1079647.859,1.99745005130768,8033.4486328125,0.00219333171844482,0.134943234324455
1079685.125,1.99742267131805,9896.3764453125,0.00219333171844482,0.143471905589104
1079722.312,1.99750518321991,11743.0162890625,0.00219333171844482,0.148066190481186
1079759.421,1.99764174938202,13633.9356640625,0.00219333171844482,0.149304644465446
1079797.281,1.99769691467285,15493.920546875,0.00219333171844482,0.149233294725418
1079834.375,1.99757925987244,17365.5603125,0.00219333171844482,0.149363742470741
1079871.968,1.99762907981873,19241.7059375,0.00219333171844482,0.149451278448105
1079909.171,1.9973327589035,19999.729140625,0.00219333171844482,0.149801374077797
1079946.406,1.997452917099,19999.73796875,0.00219333171844482,0.149478317499161
1079983.375,1.99767048835754,19999.74578125,0.00219333171844482,0.149440702795982
1080020.578,1.9978413772583,19999.73171875,0.00219333171844482,0.149247829318047
1080057.64,1.99795018672943,19999.71875,0.00219333171844482,0.149365327358246
1080094.796,1.99808405399323,19999.70625,0.00219333171844482,0.149336183667183
1080131.89,1.99821227073669,19999.87859375,0.00219333171844482,0.149356715083122
1080169.171,1.99836448192596,19999.87265625,0.00219333171844482,0.149463489055634
1080206.968,1.99843709468842,19999.866875,0.00219333171844482,0.14958305478096
1080243.906,1.99854510784149,19999.883125,0.00219333171844482,0.149353970885277
1080517.281,2.00008892059326,1525.44180664062,15.0021905899048,0.0196632077544928
1080554.312,1.99998661994934,3388.48881835937,15.0021905899048,0.0534470838308334
1080591.828,2.00005834102631,5263.3503125,15.0021905899048,0.0935296276211739
1080629.453,2.00007814884186,7146.510703125,15.0021905899048,0.115052484273911
1080666.906,1.99998661518097,9010.4487109375,15.0021905899048,0.126391523182392
1080704.265,1.99989483833313,10887.864765625,15.0021905899048,0.134251548647881
1080741.968,1.9998150062561,12754.7391015625,15.0021905899048,0.139633375406265
1080779.171,1.99963987350464,14628.8308984375,15.0021905899048,0.143390313982964
1080816.625,1.99962253570557,16495.455546875,15.0021905899048,0.146381419897079
1080854,1.99950769424438,18373.203515625,15.0021905899048,0.148314998745918
1080890.984,1.99898323059082,19993.6371875,15.0021905899048,0.148976781964302
1080928.156,1.99912414550781,19999.70734375,15.0021905899048,0.149144576191902
1080965.578,1.99923192501068,19999.713515625,15.0021905899048,0.149166975021362
1081002.531,1.99921691894531,19999.706875,15.0021905899048,0.149127324819565
1081039.859,1.99928496360779,19999.868046875,15.0021905899048,0.149263526201248
1081076.703,1.99932188510895,19999.884296875,15.0021905899048,0.149190940260887
1081113.953,1.99934336662292,20000.114609375,15.0021905899048,0.148958520293236
1081151.312,1.9993869638443,19999.850390625,15.0021905899048,0.14919296503067
1081188.531,1.99947229385376,19999.879609375,15.0021905899048,0.149117522835732
1081225.796,1.99949977397919,19999.900234375,15.0021905899048,0.148981586098671
1081497.656,2.00000848770142,572.140548095703,30.0021877288818,0.0138173615932465
1081534.953,2.00044815063477,2439.32379882812,30.0021877288818,0.0348644537478685
1081572.078,2.00051012039185,4289.07733398438,30.0021877288818,0.0752189040184021
1081609.281,2.00053346633911,6152.10669921875,30.0021877288818,0.093747698366642
1081646.468,2.00050437927246,8019.38498046875,30.0021877288818,0.0993106532096863
1081683.656,2.00037460327148,9866.7608203125,30.0021877288818,0.102514902353287
1081720.921,2.00023551940918,11716.371953125,30.0021877288818,0.105445544719696
1081758.39,2.00015620231628,13614.8769140625,30.0021877288818,0.10797284424305
1081796.343,1.99993176460266,15491.9134765625,30.0021877288818,0.110503050684929
1081833.25,1.99987422943115,17359.371796875,30.0021877288818,0.113603995740414
1081870.531,1.99980732917786,19216.464609375,30.0021877288818,0.116595047712326
1081907.781,1.99929844856262,19999.6871875,30.0021877288818,0.11783712208271
1081944.875,1.99933260440826,19999.843046875,30.0021877288818,0.11774500399828
1081982.406,1.9994539642334,19999.8415625,30.0021877288818,0.117757371366024
1082019.5,1.99946310520172,19999.860078125,30.0021877288818,0.1177742010355
1082056.796,1.99952997207642,19999.839140625,30.0021877288818,0.117753806114197
1082094.062,1.99952208995819,19999.870859375,30.0021877288818,0.117964147031307
1082131.843,1.99957349777222,19999.862109375,30.0021877288818,0.117970254421234
1082168.875,1.99955821990967,19999.865390625,30.0021877288818,0.117742632329464
1082205.812,1.99962316989899,19999.743046875,30.0021877288818,0.117963995635509
1082243.296,1.99965844631195,19999.831640625,30.0021877288818,0.117847573459148
1082515.14,2.00064757823944,1498.37236328125,45.0021858215332,0.022765573784709
1082552.656,2.00059964179993,3361.22985351563,45.0021858215332,0.0699713152647019
1082589.531,2.00062621116638,5213.545234375,45.0021858215332,0.0992058962583542
1082626.921,2.00051634788513,7086.93587890625,45.0021858215332,0.111458730101585
1082664.109,2.00042850494385,8947.0626953125,45.0021858215332,0.12015127748251
1082701.406,2.00043849945068,10797.4652734375,45.0021858215332,0.127057955265045
1082738.609,2.00026170730591,12664.4977734375,45.0021858215332,0.132982748150826
1082775.718,2.00016709327698,14524.0103515625,45.0021858215332,0.137819268703461
1082813.078,2.00002212524414,16385.683671875,45.0021858215332,0.141610300540924
1082850.343,1.99987026691437,18273.226015625,45.0021858215332,0.144660742282867
1082888.015,1.99944555282593,19977.346875,45.0021858215332,0.147005613446236
1082925.843,1.99936647891998,19999.838515625,45.0021858215332,0.147040017843246
1082962.734,1.99944090366364,19999.826875,45.0021858215332,0.147053402662277
1083000.078,1.99952361106873,19999.818203125,45.0021858215332,0.146935076117516
1083037.25,1.99947556018829,19999.825546875,45.0021858215332,0.146975687146187
1083074.687,1.99956565380096,19999.82640625,45.0021858215332,0.147070786356926
1083111.671,1.9974124288559,19999.816953125,45.0021858215332,0.146941391825676
1083149.359,1.99912585258484,19999.826953125,45.0021858215332,0.146848959326744
1083186.875,1.99921533584595,19999.83015625,45.0021858215332,0.147021068334579
1083223.75,1.99911821365356,19999.818046875,45.0021858215332,0.147117709517479
1083497.046,1.99514441490173,564.462934570313,60.0021858215332,0.0136108664795756
1083534.218,1.99959808826447,2433.67168945313,60.0021858215332,0.0538872942328453
1083571.546,1.99968788146973,4301.44893554688,60.0021858215332,0.103303790688515
1083608.656,2.00316943645477,6191.2676953125,60.0021858215332,0.124465365409851
1083646.906,1.99989304065704,8061.529453125,60.0021858215332,0.136417613625526
1083684.39,2.00011263847351,9932.703359375,60.0021858215332,0.14352892935276
1083721.718,1.99510781288147,11800.299609375,60.0021858215332,0.147757448554039
1083759.203,1.99964634418488,13670.125859375,60.0021858215332,0.149388909339905
1083796.078,1.99985977649689,15524.94171875,60.0021858215332,0.149400224685669
1083833.64,2.00185614585876,17428.439921875,60.0021858215332,0.149431602954864
1083871.546,1.99969861507416,19300.3996875,60.0021858215332,0.149490914940834
1083909,1.99912882804871,19999.80640625,60.0021858215332,0.149340239167213
1083946.062,2.00538875102997,19999.841015625,60.0021858215332,0.149530122876167
1083983.265,1.9968613910675,19999.841328125,60.0021858215332,0.149331441521645
1084020.515,1.99604988574982,19999.849375,60.0021858215332,0.14943162381649
1084058.125,1.99786172866821,19999.851171875,60.0021858215332,0.149531201720238
1084096.875,1.99987391471863,19999.87875,60.0021858215332,0.14958612382412
1084134.046,1.9996609210968,19999.863515625,60.0021858215332,0.149258695840836
1084171.515,2.00953913211823,19999.8590625,60.0021858215332,0.149717146754265
1084209.578,1.99946683883667,19999.85203125,60.0021858215332,0.149456058740616
1084246.593,2.0017330789566,19999.86390625,60.0021858215332,0.149430530667305
1084519.515,1.9934956073761,1551.20215820313,75.0021896362305,0.0309205885976553
1084558.515,2.00091010093689,3454.978828125,75.0021896362305,0.0943956571817398
1084595.812,2.0007465839386,5323.63119140625,75.0021896362305,0.124947908222675
1084633.343,1.99718667030334,7211.271640625,75.0021896362305,0.137899321317673
1084670.765,2.00014512062073,9061.473203125,75.0021896362305,0.143328741788864
1084708.093,2.00004514217377,10928.85140625,75.0021896362305,0.145528942346573
1084745.359,2.00992742061615,12805.817265625,75.0021896362305,0.146675142645836
1084783.171,2.00019674301147,14672.86515625,75.0021896362305,0.147875400185585
1084820.093,2.00020186901093,16539.5587890625,75.0021896362305,0.148502863645554
1084857.343,1.99408781528473,18399.664765625,75.0021896362305,0.148874682188034
1084894.64,1.99819875717163,19998.9315625,75.0021896362305,0.149436683058739
1084931.734,1.99894582271576,19999.8415625,75.0021896362305,0.149525928497314
1084969.328,2.00433740615845,19999.783671875,75.0021896362305,0.149505979418755
1085007.671,1.99958452701569,19999.826484375,75.0021896362305,0.149504957795143
1085044.875,1.99982874393463,19999.841171875,75.0021896362305,0.149303621053696
1085082.234,2.00558010578156,19999.8346875,75.0021896362305,0.149489313364029
1085119.718,1.99950487136841,19999.839453125,75.0021896362305,0.149225703477859
1085156.843,1.9993957901001,19999.845,75.0021896362305,0.149485365748405
1085195.203,2.00958324432373,20000.104453125,75.0021896362305,0.149582477211952
1085233.203,1.99966867923737,19999.82,75.0021896362305,0.149418066740036
1085505.671,2.00103061676025,564.328305664063,90.0021896362305,0.0137031808868051
1085544.265,2.00066534996033,2494.04391601563,90.0021896362305,0.0609093171358109
1085581.468,2.00050028800964,4347.595078125,90.0021896362305,0.106101135909557
1085618.484,2.00048614501953,6203.87619140625,90.0021896362305,0.125240776538849
1085657.656,1.99931340694427,8157.51064453125,90.0021896362305,0.132444509863853
1085694.734,2.00074005126953,10016.5179296875,90.0021896362305,0.135795357823372
1085732.093,2.00070033073425,11880.9236328125,90.0021896362305,0.138992246389389
1085769.343,1.99899479866028,13744.8685546875,90.0021896362305,0.140569960474968
1085806.515,2.00220542430878,15596.4496875,90.0021896362305,0.141676592826843
1085843.718,2.00292414665222,17462.099296875,90.0021896362305,0.14250781416893
1085881.859,2.0013009262085,19379.29390625,90.0021896362305,0.142982793450356
1085919.078,1.99969409942627,19999.8165625,90.0021896362305,0.143113082051277
1085956.296,2.00005619049072,19999.83609375,90.0021896362305,0.142996084094048
1085993.312,2.00159852027893,19999.82875,90.0021896362305,0.143111680746079
1086030.609,2.00187251091003,19999.810703125,90.0021896362305,0.143215434551239
1086068.656,2.00293836116791,19999.824140625,90.0021896362305,0.143054346442223
1086107.218,2.00122883319855,19999.821015625,90.0021896362305,0.143233715891838
1086144.437,1.99985210418701,19999.818125,90.0021896362305,0.143087944984436
1086181.64,2.00023587226868,19999.82109375,90.0021896362305,0.143174029588699
1086219.281,2.00232310295105,19999.830390625,90.0021896362305,0.143258959054947
1086256.375,1.99965463161469,19999.81953125,90.0021896362305,0.142937368750572
1086528.39,1.99832402229309,1519.83783203125,105.00218963623,0.0354492802917957
1086566.25,2.00136834144592,3384.32642578125,105.00218963623,0.092054331600666
1086603.171,2.00091627120972,5262.1805078125,105.00218963623,0.128777738213539
1086641.078,2.00167270183563,7181.1718359375,105.00218963623,0.139718638062477
1086679.437,2.00016716003418,9050.7037890625,105.00218963623,0.142573338150978
1086716.921,2.00029059410095,10914.4944921875,105.00218963623,0.144522157907486
1086753.859,1.99361196517944,12810.8344921875,105.00218963623,0.146105588078499
1086792.578,2.00071273803711,14708.5693359375,105.00218963623,0.147162086963654
1086830.203,2.00045441627502,16600.9040625,105.00218963623,0.14817601621151
1086867.671,1.9965021276474,18467.623046875,105.00218963623,0.148684768080711
1086905.046,1.9992655134201,19999.480078125,105.00218963623,0.148935502767563
1086942.375,2.00119567871094,19999.7684375,105.00218963623,0.149153017997742
1086980.234,1.99710865020752,19999.815546875,105.00218963623,0.149089125394821
1087017.5,2.00009867668152,19999.809921875,105.00218963623,0.149136911034584
1087054.937,2.00000509738922,19999.794609375,105.00218963623,0.148922111988068
1087092.453,2.00006217956543,19999.814375,105.00218963623,0.148828037977219
1087129.812,1.99937782764435,19999.79828125,105.00218963623,0.148999697566032
1087167.078,2.00126640319824,19999.815859375,105.00218963623,0.148928641676903
1087205.437,2.00230495929718,19999.808203125,105.00218963623,0.149096081256866
1087242.578,2.00001694202423,19999.80828125,105.00218963623,0.14897370994091
1091554.843,1.99613903999329,575.361846923828,120.00218963623,0.0145308645069599
1091592.046,1.99640200138092,2438.093984375,120.00218963623,0.0691779001057148
1091629.562,1.99686550140381,4310.63397460938,120.00218963623,0.115714395642281
1091667.796,1.99704123973846,6222.4068359375,120.00218963623,0.135730826258659
1091705.125,1.99726959705353,8086.28982421875,120.00218963623,0.143440116643906
1091742.359,1.99741097450256,9948.8625,120.00218963623,0.147187414765358
1091779.562,1.99740238189697,11804.0621875,120.00218963623,0.14872184753418
1091816.828,1.99748237609863,13670.2386328125,120.00218963623,0.149636545181274
1091854.609,1.99748030662537,15572.847265625,120.00218963623,0.149997108578682
1091892.64,1.99748652935028,17477.186171875,120.00218963623,0.150020160675049
1091930.359,1.99760430335999,19354.31515625,120.00218963623,0.150164366960526
1091967.484,1.99716698646545,19999.899453125,120.00218963623,0.150102351903915
1092004.625,1.9974036359787,19999.91109375,120.00218963623,0.1503185993433
1092042.328,1.99758923053741,19999.909375,120.00218963623,0.150226147174835
1092079.64,1.99780191421509,19999.903515625,120.00218963623,0.150167188048363
1092118.078,1.99791578769684,19999.900390625,120.00218963623,0.150194820165634
1092155.218,1.99805039405823,19999.883984375,120.00218963623,0.150111338496208
1092192.453,1.99824650287628,19999.8975,120.00218963623,0.150200498104095
1092229.64,1.99840626239777,19999.87921875,120.00218963623,0.150275592803955
1092267.25,1.99841979980469,19999.903359375,120.00218963623,0.150179963707924
1092304.531,1.99855263710022,19999.878671875,120.00218963623,0.150301678180695
1092577.656,2.0001606798172,1496.20364257813,135.002197265625,0.0359102233499289
1092614.718,1.999978723526,3365.99067382813,135.002197265625,0.0979056859016419
1092652.062,2.00002430438995,5220.72955078125,135.002197265625,0.124734600484371
1092689.421,2.00006227493286,7089.8939453125,135.002197265625,0.132911341786385
1092727.093,2.00000818252563,8975.5915625,135.002197265625,0.13724477827549
1092764.453,1.99991379737854,10827.9727734375,135.002197265625,0.141943595409393
1092801.937,1.99986131191254,12717.194921875,135.002197265625,0.145627772212028
1092839.39,1.99971053600311,14586.229375,135.002197265625,0.147228032946587
1092877.531,1.99964133739471,16504.153828125,135.002197265625,0.148721086382866
1092914.796,1.99952864170074,18352.86171875,135.002197265625,0.149420613050461
1092951.734,1.99898905277252,19991.9128125,135.002197265625,0.149714774489403
1092988.937,1.99907202243805,19999.8178125,135.002197265625,0.149861794710159
1093026.296,1.99919072151184,19999.853203125,135.002197265625,0.149854603409767
1093064.125,1.99922928333282,19999.86,135.002197265625,0.149899834990501
1093101.531,1.99926280021667,19999.840625,135.002197265625,0.14960035443306
1093138.687,1.99927780151367,19999.830390625,135.002197265625,0.149832206368446
1093176.187,1.99937247276306,19999.84203125,135.002197265625,0.149832772016525
1093213.5,1.99945310592651,19999.838203125,135.002197265625,0.149608864188194
1093250.64,1.99938992023468,19999.852421875,135.002197265625,0.149681805968285
1093287.875,1.99943565368652,19999.82875,135.002197265625,0.14977725148201
1093561.109,2.00057815551758,572.501811523437,150.002197265625,0.0136528208479285
1093598.453,2.00050520896912,2440.9563671875,150.002197265625,0.0614279994368553
1093635.703,2.00059448242187,4318.49850585937,150.002197265625,0.112175081968308
1093673.375,2.0005361366272,6178.95203125,150.002197265625,0.129300438165665
1093710.687,2.00048110961914,8043.98111328125,150.002197265625,0.132648460865021
1093747.781,2.00037620544434,9888.5429296875,150.002197265625,0.133075392246246
1093784.781,2.00026941299438,11751.15921875,150.002197265625,0.133302167654037
1093822.015,2.00009969711304,13610.4748828125,150.002197265625,0.133422920107841
1093859.343,1.99999628067017,15481.2925,150.002197265625,0.133598898053169
1093896.796,1.99989358901978,17354.8490625,150.002197265625,0.133646614551544
1093933.796,1.9997601890564,19210.786640625,150.002197265625,0.133909209370613
1093971.578,1.99929759025574,19999.8115625,150.002197265625,0.133813497424126
1094009.281,1.99939472198486,19999.939375,150.002197265625,0.134161588549614
1094046.671,1.99932548999786,19999.818515625,150.002197265625,0.133990880846977
1094084.515,1.99945137023926,19999.820078125,150.002197265625,0.133844172954559
1094122.093,1.99939012527466,19999.815078125,150.002197265625,0.134020859003067
1094159.406,1.99952888965607,19999.831875,150.002197265625,0.134062485694885
1094197.25,1.9995693397522,19999.827421875,150.002197265625,0.133746225237846
1094234.234,1.99961083889008,19999.835703125,150.002197265625,0.134063428640366
1094271.531,1.99956790924072,19999.798046875,150.002197265625,0.133913660049438
1094309,1.99962285041809,19999.80640625,150.002197265625,0.133869738578796
1094581.64,2.00073542118073,1501.77235839844,165.002197265625,0.0276318713277578
1094619.218,2.00054363250732,3379.81383789063,165.002197265625,0.0801758852601051
1094656.718,2.00064059257507,5249.49751953125,165.002197265625,0.116404505670071
1094693.921,2.00061621665955,7108.0553125,165.002197265625,0.129781872034073
1094731.25,2.00045969009399,8973.0630859375,165.002197265625,0.134340723752975
1094769.125,2.00030785560608,10867.0132421875,165.002197265625,0.135999838113785
1094806.39,2.00022880077362,12717.10921875,165.002197265625,0.140201123952866
1094843.375,2.00015311717987,14583.3574609375,165.002197265625,0.143871042132378
1094880.718,2.00000294208527,16439.3819140625,165.002197265625,0.146436217427254
1094917.734,1.99989352703094,18303.297421875,165.002197265625,0.14841650724411
1094955,1.99935590267181,19983.0359375,165.002197265625,0.149429315924644
1094992.531,1.99940421104431,20000.07453125,165.002197265625,0.149202093482018
1095029.625,1.99945021152496,19999.817578125,165.002197265625,0.14942610681057
1095066.984,1.99944962024689,19999.770390625,165.002197265625,0.149553758502007
1095105.078,1.9998674249649,19999.798671875,165.002197265625,0.149477890729904
1095141.968,1.99912068367004,19999.802109375,165.002197265625,0.149200180768967
1095179.843,1.99730384349823,19999.78171875,165.002197265625,0.14945022881031
1095216.937,1.99882998466492,19999.800078125,165.002197265625,0.149442552924156
1095254.296,1.99870150566101,19999.7846875,165.002197265625,0.149463602304459
1095291.656,1.9978880405426,19999.75828125,165.002197265625,0.149448025226593
1095563.765,1.99915638446808,566.936260986328,180.002197265625,0.0125415903329849
1095602.171,2.00303452968597,2484.28841796875,180.002197265625,0.0409626607596874
1095639.656,2.00018787384033,4365.7844921875,180.002197265625,0.0854022806882858
1095677.343,2.00039823055267,6242.449140625,180.002197265625,0.118462603092194
1095714.578,1.9992388677597,8100.55865234375,180.002197265625,0.136815009713173
1095751.89,1.99942320823669,9982.9741796875,180.002197265625,0.14547711789608
1095789.531,1.9996649646759,11852.7584375,180.002197265625,0.149156586527824
1095828.562,1.99748994350433,13787.9512109375,180.002197265625,0.150082870721817
1095865.593,1.99992500782013,15653.9653515625,180.002197265625,0.150247955322266
1095902.953,2.00007359027863,17525.416796875,180.002197265625,0.150387862324715
1095941.656,1.99818903446198,19463.608515625,180.002197265625,0.150701658725739
1095978.828,2.00001132488251,19999.98234375,180.002197265625,0.150802130103111
1096016.39,2.00029722690582,20000.0134375,180.002197265625,0.150839877128601
1096056.015,1.99903868675232,19999.97390625,180.002197265625,0.150970944166183
1096094.296,1.9995352268219,19999.96625,180.002197265625,0.150953996181488
1096131.531,1.99968577384949,19999.99671875,180.002197265625,0.150979853272438
1096168.312,1.99696180820465,20000.012109375,180.002197265625,0.150696818828583
1096205.687,1.99713799476624,19999.9990625,180.002197265625,0.151120069622993
1096242.765,1.99697510242462,19999.979140625,180.002197265625,0.150847142934799
1096280.953,1.99996936798096,19999.99078125,180.002197265625,0.150761714577675
1096317.859,1.99964803218842,19999.99296875,180.002197265625,0.150922103524208
1096590.765,2.0015921163559,1522.00716796875,195.002197265625,0.0193832030892372
1096628.109,2.00080741405487,3368.05634765625,195.002197265625,0.0528053413331509
1096665.421,2.00060715675354,5242.58896484375,195.002197265625,0.09361323595047
1096702.609,2.00052840232849,7099.95380859375,195.002197265625,0.116531544029713
1096741.687,1.99913505554199,9052.840703125,195.002197265625,0.128818277716637
1096778.875,2.0006963634491,10907.0414453125,195.002197265625,0.136428864002228
1096816.734,2.00062328338623,12793.9601953125,195.002197265625,0.141647862195969
1096854.109,2.00128383159637,14677.9003125,195.002197265625,0.145739212036133
1096891.421,1.99900995731354,16548.7678515625,195.002197265625,0.1488788241148
1096928.703,1.9975327205658,18419.683046875,195.002197265625,0.150268636345863
1096967.843,1.99939682483673,19999.81140625,195.002197265625,0.150807678103447
1097005.078,1.99962850093842,19999.824609375,195.002197265625,0.150692148208618
1097042.234,1.99991380214691,19999.820625,195.002197265625,0.150691565871239
1097079.406,1.99875779628754,19999.825234375,195.002197265625,0.150621809959412
1097116.687,1.9995380115509,19999.837734375,195.002197265625,0.150532208681107
1097154.171,1.99933141231537,19999.8303125,195.002197265625,0.150829427838326
1097192.75,1.99990698337555,19999.831328125,195.002197265625,0.150726356506348
1097230.171,1.99969590187073,19999.841015625,195.002197265625,0.150842781066895
1097267.39,1.99993895053864,19999.8359375,195.002197265625,0.150794358253479
1097304.75,1.9978918504715,19999.797421875,195.002197265625,0.150639745593071
1097576.906,1.99993438243866,571.723134765625,210.002197265625,0.0137415095791221
1097614.468,1.98794244766235,2442.6896875,210.002197265625,0.0330891507863998
1097652.343,2.00123607158661,4343.40283203125,210.002197265625,0.0752684035897255
1097689.593,2.00077479362488,6207.838828125,210.002197265625,0.094195953309536
1097727.125,2.0055621099472,8105.91509765625,210.002197265625,0.100092333257198
1097765.687,2.00026512622833,10008.0601171875,210.002197265625,0.10332806199789
1097802.734,1.99999287128448,11865.30859375,210.002197265625,0.106011641919613
1097840.625,1.990074634552,13818.154609375,210.002197265625,0.10881083458662
1097880.093,2.00041773796082,15733.050078125,210.002197265625,0.112083189189434
1097917.5,2.00000329971313,17605.86296875,210.002197265625,0.114853974282742
1097954.718,2.00769172668457,19468.14984375,210.002197265625,0.118038571178913
1097992.343,1.99870404720306,19999.83078125,210.002197265625,0.118243821263313
1098028.984,1.99709329605103,19999.8534375,210.002197265625,0.118171892166138
1098066.187,2.00494508743286,19999.856328125,210.002197265625,0.118667755126953
1098104.687,1.99952167987823,19999.8421875,210.002197265625,0.118482469916344
1098141.906,1.9995149564743,19999.85078125,210.002197265625,0.118585478365421
1098179.156,2.00917900562286,19999.841953125,210.002197265625,0.118965661525726
1098217.531,1.99961928367615,19999.826875,210.002197265625,0.118478136360645
1098255.093,1.99870568275452,19999.836796875,210.002197265625,0.118340278565884
1098292.234,2.0032856798172,19999.858046875,210.002197265625,0.118400593996048
1098330.609,1.99999744415283,19999.78125,210.002197265625,0.118529210686684
1098603.75,2.00150046348572,1517.66229003906,225.002197265625,0.022642837613821
1098640.796,2.00095158576965,3369.68930664063,225.002197265625,0.0683781994879246
1098678.281,2.00044233322144,5244.14728515625,225.002197265625,0.0977311021089554
1098715.515,2.00031836509705,7111.980625,225.002197265625,0.108879013061523
1098754.875,2.00100224971771,9071.035234375,225.002197265625,0.11810410797596
1098792.125,2.00056984901428,10922.22515625,225.002197265625,0.123719015419483
1098829.828,2.00469462871552,12805.776796875,225.002197265625,0.130812456607819
1098866.609,2.0004158782959,14668.2645703125,225.002197265625,0.135607585310936
1098904.328,1.99985744476318,16537.6737109375,225.002197265625,0.140065302252769
1098941.343,1.98681948661804,18390.7171875,225.002197265625,0.14313766181469
1098978.828,1.9994935131073,19999.107734375,225.002197265625,0.146066626310349
1099015.609,1.99959441661835,19999.84953125,225.002197265625,0.14612804889679
1099052.812,1.99963625431061,19999.839921875,225.002197265625,0.146294769644737
1099089.921,1.99846364498138,19999.841640625,225.002197265625,0.14624444425106
1099127.515,1.99943653583527,19999.846953125,225.002197265625,0.146098467111588
1099165.484,2.00032203197479,19999.83703125,225.002197265625,0.146116985678673
1099203.515,1.99933875083923,19999.8409375,225.002197265625,0.146336227059364
1099240.781,1.99984228610992,19999.83421875,225.002197265625,0.14593279838562
1099278.156,2.00921335220337,19999.836015625,225.002197265625,0.146629382967949
1099315.406,1.99990564823151,19999.861171875,225.002197265625,0.14623889029026
1103623.89,1.99610563755035,579.476030273437,240.002197265625,0.0137484698742628
1103661.515,1.9965695476532,2444.08143554688,240.002197265625,0.0523918633162975
1103698.515,1.99681936264038,4305.19920898438,240.002197265625,0.100384024977684
1103735.687,1.99706043243408,6152.06232421875,240.002197265625,0.122272649109364
1103772.921,1.99734199523926,8012.70595703125,240.002197265625,0.134700650572777
1103809.906,1.99741599082947,9877.438671875,240.002197265625,0.142378172278404
1103847.296,1.99745034694672,11740.4479296875,240.002197265625,0.147941051721573
1103884.609,1.99755828857422,13605.1025,240.002197265625,0.149951280355453
1103921.718,1.99744888305664,15466.5093359375,240.002197265625,0.150522369742394
1103959.156,1.99751188755035,17328.534375,240.002197265625,0.150464461445808
1103996.062,1.99760442256927,19198.448125,240.002197265625,0.15055369079113
1104033.609,1.99726085186005,19999.85234375,240.002197265625,0.150466294884682
1104071.14,1.99741503715515,19999.84625,240.002197265625,0.150626907944679
1104108.593,1.99761656284332,19999.843515625,240.002197265625,0.150651333332062
1104145.734,1.99775794029236,19999.839453125,240.002197265625,0.150678230524063
1104182.859,1.99788733959198,19999.840078125,240.002197265625,0.150671431422234
1104220.187,1.99803868770599,19999.844921875,240.002197265625,0.150439538359642
1104257.875,1.99821959972382,19999.8175,240.002197265625,0.150497688651085
1104294.968,1.99836550712585,19999.837890625,240.002197265625,0.150761098861694
1104332.562,1.99836987495422,19999.829453125,240.002197265625,0.150537522435188
1104370.14,1.9985999917984,19999.8271875,240.002197265625,0.150603258609772
1104642.703,2.00048914909363,1505.90098144531,255.002197265625,0.0289836613833904
1104679.656,1.99993211746216,3356.53705078125,255.002197265625,0.089593271613121
1104716.953,1.99991940975189,5214.6034375,255.002197265625,0.122696581184864
1104754.031,1.999885430336,7074.2284375,255.002197265625,0.136214203238487
1104791.359,1.99986810207367,8929.735390625,255.002197265625,0.142863137722015
1104828.39,1.99983557224274,10792.1245703125,255.002197265625,0.145732716917992
1104865.531,1.99977383613586,12634.525546875,255.002197265625,0.147517713904381
1104902.671,1.99969771385193,14506.6274609375,255.002197265625,0.148582953214645
1104939.734,1.99959461688995,16367.271875,255.002197265625,0.149374325871468
1104977.234,1.99955075740814,18240.999453125,255.002197265625,0.149930484890938
1105014.359,1.99919865131378,19964.40359375,255.002197265625,0.150311853885651
1105051.5,1.99906807422638,19999.85078125,255.002197265625,0.150148229002953
1105089.671,1.9990756893158,19999.823984375,255.002197265625,0.15023307621479
1105126.89,1.99919916629791,19999.829609375,255.002197265625,0.150079073309898
1105163.781,1.99925325870514,19999.82375,255.002197265625,0.150293797850609
1105201.312,1.9992945766449,19999.811171875,255.002197265625,0.150284678339958
1105238.468,1.99938261032105,19999.8178125,255.002197265625,0.150378926992416
1105276.156,1.9993624830246,19999.82890625,255.002197265625,0.150528563261032
1105313.093,1.99944947242737,19999.82734375,255.002197265625,0.15038373708725
1105350.89,1.99950547218323,19999.8253125,255.002197265625,0.150033542513847
1105622.812,2.00051661491394,578.206766357422,270.002197265625,0.0136257003620267
1105660.203,2.00043882846832,2445.6075,270.002197265625,0.0575052390992641
1105697.453,2.00038296699524,4307.74114257812,270.002197265625,0.107202309072018
1105734.75,2.00036794662476,6170.621015625,270.002197265625,0.128166983127594
1105772.078,2.00028787136078,8033.2509765625,270.002197265625,0.135136500000954
1105809.328,2.00028086662292,9896.814921875,270.002197265625,0.13757808804512
1105847.078,2.00019103050232,11782.799765625,270.002197265625,0.139838494062424
1105884.312,2.00007848262787,13647.16171875,270.002197265625,0.141349137425423
1105921.75,2.00000110149384,15521.1626953125,270.002197265625,0.142141134142876
1105958.953,1.99993051528931,17392.24,270.002197265625,0.143397033214569
1105996.5,1.99995902061462,19263.57,270.002197265625,0.144242551922798
1106033.89,1.9993155002594,19999.83921875,270.002197265625,0.144347879886627
1106071.015,1.99936938762665,19999.8590625,270.002197265625,0.144745490550995
1106108.5,1.99946813583374,19999.834765625,270.002197265625,0.144777287840843
1106145.843,1.99950720310211,19999.85296875,270.002197265625,0.144661878943443
1106183.593,1.99944645881653,19999.85078125,270.002197265625,0.144669281840324
1106221.406,1.99957349300385,19999.844140625,270.002197265625,0.144497913122177
1106258.593,1.99956404209137,19999.85421875,270.002197265625,0.144575498104095
1106296.062,1.99960601806641,19999.844921875,270.002197265625,0.144467243552208
1106333.796,1.99966490268707,19999.849375,270.002197265625,0.144609956741333
1106371.234,1.9997003030777,19999.842890625,270.002197265625,0.144576259851456
1106643.625,2.00085949420929,1506.243203125,285.002197265625,0.0336219209432602
1106680.89,2.00036247730255,3382.8707421875,285.002197265625,0.0904403460025787
1106719,2.00038931846619,5276.8760546875,285.002197265625,0.127191679179668
1106756.375,2.00038913726807,7142.509765625,285.002197265625,0.139126869440079
1106793.25,2.00033394813538,8968.4569140625,285.002197265625,0.14270643889904
1106830.843,2.00023035526276,10850.8728515625,285.002197265625,0.145052782893181
1106867.875,2.00018286705017,12714.5153125,285.002197265625,0.146351919770241
1106906.703,2.00009767055511,14650.21421875,285.002197265625,0.1474704682827
1106943.875,2.00006953239441,16519.28828125,285.002197265625,0.147859653234482
1106981.078,1.99994945526123,18388.421875,285.002197265625,0.148629377484322
1107018.812,1.99923029899597,19999.21375,285.002197265625,0.148923973441124
1107056.296,1.99945366382599,19999.977109375,285.002197265625,0.148827425837517
1107093.578,1.99951605796814,19999.9934375,285.002197265625,0.149356841444969
1107130.968,1.99948635101318,20000.005078125,285.002197265625,0.148961784243584
1107168.14,2.00014498233795,20000.010234375,285.002197265625,0.149040483236313
1107205.562,1.99914186954498,19999.9903125,285.002197265625,0.148986276388168
1107242.921,1.99827608108521,19999.97421875,285.002197265625,0.148938034772873
1107280.078,1.99880088806152,19999.968984375,285.002197265625,0.149113042354584
1107317.968,1.99873352527618,19999.99953125,285.002197265625,0.148821778893471
1107355.156,1.99788007736206,20000.001171875,285.002197265625,0.148932068347931
1107627.687,1.99979266166687,574.689505615234,300.002197265625,0.0146444573253393
1107665.75,2.00352717399597,2492.81821289063,300.002197265625,0.0698150451481342
1107703.437,2.00014306545258,4354.9575390625,300.002197265625,0.115388048887253
1107740.843,2.00017446994781,6247.41388671875,300.002197265625,0.137141375541687
1107778.5,2.00258920669556,8107.70607421875,300.002197265625,0.144280723929405
1107815.906,1.99963977336884,9994.0599609375,300.002197265625,0.14715704023838
1107853.375,1.99942977905273,11854.506640625,300.002197265625,0.148713175058365
1107891.812,2.00101037025452,13772.89625,300.002197265625,0.149392659068108
1107929.109,1.99974884986877,15629.0881640625,300.002197265625,0.149771970510483
1107966.328,1.99977269649506,17495.46609375,300.002197265625,0.149756256937981
1108003.296,1.99486223220825,19346.23984375,300.002197265625,0.150022958517075
1108040.625,1.99875426292419,19999.851640625,300.002197265625,0.150090312957764
1108077.765,1.99940001964569,19999.886640625,300.002197265625,0.149988094568253
1108116.703,1.9984308385849,19999.880546875,300.002197265625,0.149891501069069
1108154,1.99941796302795,19999.8775,300.002197265625,0.149930331707001
1108192.031,1.99956618309021,19999.87875,300.002197265625,0.149895574450493
1108229.093,2.00147840976715,19999.865234375,300.002197265625,0.149912207126617
1108266.453,1.99857353687286,19999.8621875,300.002197265625,0.149908031821251
1108303.625,1.99810979366303,19999.8684375,300.002197265625,0.149937205314636
1108341.421,1.99548534393311,19999.848671875,300.002197265625,0.149951022267342
1108379.031,1.99995993614197,19999.857734375,300.002197265625,0.149977195858955
1108651.765,2.00119410037994,1517.06697753906,315.002197265625,0.0360141883045435
1108688.734,2.00245267868042,3367.5052734375,315.002197265625,0.0980958592891693
1108726.062,2.00018775939941,5229.550078125,315.002197265625,0.125276816785336
1108763.125,2.00013467311859,7087.00435546875,315.002197265625,0.133034298419952
1108801.5,2.00113068580627,8990.0934375,315.002197265625,0.138055559396744
1108838.453,2.00042432785034,10848.2855078125,315.002197265625,0.143040955662727
1108875.828,2.00069347381592,12717.739296875,315.002197265625,0.146266393661499
1108913.093,2.00163491249084,14580.364921875,315.002197265625,0.147787951827049
1108950.343,1.99971903800964,16446.5891796875,315.002197265625,0.148795256614685
1108987.656,2.00181029319763,18323.757890625,315.002197265625,0.149084818959236
1109025.765,2.00245353221893,19993.362734375,315.002197265625,0.149153062701225
1109063.468,1.99945585250854,19999.838125,315.002197265625,0.149218375086784
1109100.984,1.99957993507385,19999.850703125,315.002197265625,0.149359117150307
1109138.421,1.99364978313446,19999.86359375,315.002197265625,0.149391102194786
1109175.953,1.99972570896149,19999.845546875,315.002197265625,0.149307949542999
1109213.062,2.00169930458069,19999.8484375,315.002197265625,0.149178735613823
1109250.781,1.99688509464264,19999.842578125,315.002197265625,0.149283121228218
1109288.468,1.99998197078705,19999.835234375,315.002197265625,0.149209558367729
1109326.265,1.99989385128021,19999.851796875,315.002197265625,0.149181973338127
1109363.187,2.00795636177063,19999.84859375,315.002197265625,0.149067190885544
1109636.046,1.99944467544556,575.041131591797,330.002197265625,0.0136766097322106
1109673.39,2.00033234596252,2440.7723828125,330.002197265625,0.0635434120893478
1109711.14,2.00468053340912,4323.50752929688,330.002197265625,0.113114753961563
1109748.312,2.00074589729309,6182.95759765625,330.002197265625,0.129387358427048
1109785.656,2.0010161113739,8044.814140625,330.002197265625,0.132633183598518
1109822.812,2.00111138343811,9903.78515625,330.002197265625,0.132737674117088
1109860.046,2.00001470565796,11767.4034375,330.002197265625,0.133079684972763
1109897.375,1.99981413841248,13630.538671875,330.002197265625,0.133080626726151
1109936.171,2.00042177677155,15575.039453125,330.002197265625,0.133107035756111
1109973.171,2.00009519100189,17428.1115625,330.002197265625,0.133243538141251
1110011.031,2.00024322032928,19310.055390625,330.002197265625,0.133753811120987
1110047.984,2.00123467445374,19999.84671875,330.002197265625,0.133893945813179
1110085.265,1.99772330760956,19999.813125,330.002197265625,0.133747835755348
1110122.359,1.99636855602264,19999.83265625,330.002197265625,0.133750413060188
1110160.734,1.99971339225769,19999.8303125,330.002197265625,0.134052264690399
1110197.953,1.99973533153534,19999.846484375,330.002197265625,0.133977874517441
1110235.156,2.00007633686066,19999.848203125,330.002197265625,0.133963836431503
1110272.25,1.99817095279694,19999.84453125,330.002197265625,0.133871276378632
1110309.671,1.99944887161255,19999.812734375,330.002197265625,0.133976836204529
1110346.859,1.99921455383301,19999.806875,330.002197265625,0.13390088737011
1110385.062,1.99922209739685,19999.825234375,330.002197265625,0.134002393484116