File: EXPORT_field _0T_6T_angle_0_330deg_2K.dat
Time Stamp (sec),Temperature (K),Magnetic Field (Oe),Sample Position (degrees),Bridge 1 Resistance (Ohms)
1181997.671,1.99730827013652,444.475956217448,30.0022563934326,0.0129879418760538
1182038.187,1.99765399297078,2469.92506510417,30.0022563934326,0.0348822616040707
1182078.296,1.99782780806224,4461.69088541667,30.0022563934326,0.0770003467798233
1182118.281,1.99811249574025,6471.12080078125,30.0022563934326,0.095039468506972
1182158.421,1.99825417995453,8476.48671875,30.0022563934326,0.100004695852598
1182198.328,1.99817311763763,10469.6193359375,30.0022563934326,0.103148092329502
1182238.328,1.99799558321635,12474.666796875,30.0022563934326,0.106412391364574
1182278.296,1.99801528453827,14472.03359375,30.0022563934326,0.10909528285265
1182318.234,1.99804467360179,16468.2560546875,30.0022563934326,0.112009859581788
1182358.203,1.99812060197194,18475.2576822917,30.0022563934326,0.115074829757214
1182398.187,1.9980815966924,20464.0182291667,30.0022563934326,0.118364246189594
1182438.062,1.99820488293966,22470.1776041667,30.0022563934326,0.121821675201257
1182478,1.99827833970388,24469.314453125,30.0022563934326,0.12539158364137
1182517.89,1.99835394223531,26468.10546875,30.0022563934326,0.128600917259852
1182557.906,1.99838509559631,28477.304296875,30.0022563934326,0.13249439795812
1182597.843,1.99849053223928,30472.2309895833,30.0022563934326,0.136168377598127
1182637.828,1.9985565106074,32473.73125,30.0022563934326,0.139366591970126
1182677.671,1.9986138343811,34471.5669270833,30.0022563934326,0.142642915248871
1182717.625,1.99872568448385,36470.0544270833,30.0022563934326,0.145594916741053
1182757.656,1.99880555470785,38471.909375,30.0022563934326,0.147457291682561
1182797.515,1.99894308249156,40459.4729166667,30.0022563934326,0.148448992768923
1182837.453,1.99899164835612,42468.46015625,30.0022563934326,0.148813929160436
1182877.328,1.99901266098022,44467.02890625,30.0022563934326,0.149354519446691
1182917.328,1.99914243221283,46468.2057291667,30.0022563934326,0.149162885546684
1182957.359,1.99919248421987,48463.4385416667,30.0022563934326,0.149140545725822
1182997.296,1.99920395215352,50473.3065104167,30.0022563934326,0.149412865440051
1183037.062,1.99930673440297,52476.7515625,30.0022563934326,0.14931522210439
1183076.703,1.99935917854309,54471.4442708333,30.0022563934326,0.149276272455851
1183116.39,1.99940704504649,56477.8817708333,30.0022563934326,0.149562123417854
1183156.078,1.9994330406189,58473.3078125,30.0022563934326,0.149388970931371
1183197.578,1.99931135972341,59999.7354166667,30.0022563934326,0.149401923020681
1183299.468,1.99942934513092,58529.85390625,45.002254486084,0.149226529399554
1183339.687,1.99945712089539,56532.7893229167,45.002254486084,0.149474470814069
1183380.062,1.99945166905721,54536.2122395833,45.002254486084,0.149537524580956
1183420.156,1.99945770899455,52530.0015625,45.002254486084,0.149176851908366
1183460.296,1.99951586723328,50535.0140625,45.002254486084,0.149379233519236
1183500.609,1.99947466850281,48515.3723958333,45.002254486084,0.149410190184911
1183540.921,1.99953422546387,46533.4020833333,45.002254486084,0.149141704042753
1183580.984,1.99951984087626,44535.8526041667,45.002254486084,0.149163297812144
1183621.359,1.99957099755605,42541.9471354167,45.002254486084,0.149495220184326
1183661.593,1.99957313537598,40532.7049479167,45.002254486084,0.14934755563736
1183701.718,1.99959061940511,38531.77421875,45.002254486084,0.149527591466904
1183742.14,1.99959166049957,36518.928125,45.002254486084,0.149202135205269
1183782.25,1.99961047172546,34533.04609375,45.002254486084,0.149334174394608
1183822.5,1.99965520699819,32530.8227864583,45.002254486084,0.149125175674756
1183862.812,1.99963585535685,30538.6592447917,45.002254486084,0.149239501357079
1183902.89,1.99963955879211,28535.0130208333,45.002254486084,0.149337056279182
1183943.171,1.9997766494751,26535.08125,45.002254486084,0.149108338356018
1183983.343,1.99969626267751,24541.8557291667,45.002254486084,0.14915308256944
1184023.5,1.99976936976115,22524.9859375,45.002254486084,0.148830036322276
1184063.578,1.99983909924825,20520.8553385417,45.002254486084,0.147414094209671
1184103.562,1.99986054897308,18534.9708333333,45.002254486084,0.144871139526367
1184143.687,1.9998789469401,16527.9912109375,45.002254486084,0.141596656044324
1184183.812,1.99994422594706,14541.5837890625,45.002254486084,0.137709856033325
1184223.906,2.0000009059906,12530.9327473958,45.002254486084,0.132214300831159
1184264.078,2.00007472832998,10525.8772135417,45.002254486084,0.125841413935026
1184304.125,2.00013887882233,8528.39661458333,45.002254486084,0.118086822330952
1184344.187,2.00010921955109,6527.41282552083,45.002254486084,0.108023372292519
1184384.25,2.00043228467305,4539.94436848958,45.002254486084,0.0910735343893369
1184424.359,2.00043716430664,2526.06293945313,45.002254486084,0.0449125245213509
1184464.234,2.00139790376027,528.247566731771,45.002254486084,0.0132879721000791
1184574.781,2.00039496421814,437.068522135417,90.0022506713867,0.0123603796586394
1184615.265,2.00066749254862,2471.76479492187,90.0022506713867,0.0602517046034336
1184655.296,2.00061831474304,4469.30862630208,90.0022506713867,0.107838528851668
1184695.265,2.00059382120768,6467.7478515625,90.0022506713867,0.126923491557439
1184735.328,2.00045598347982,8469.840625,90.0022506713867,0.133266386389732
1184775.39,2.00043470064799,10462.6612630208,90.0022506713867,0.136440283060074
1184815.406,2.00029541651408,12471.0974609375,90.0022506713867,0.139441210031509
1184855.312,2.00028115908305,14471.8041015625,90.0022506713867,0.141178134083748
1184895.218,2.00008420149485,16468,90.0022506713867,0.142280741532644
1184935.25,1.99996653397878,18471.116796875,90.0022506713867,0.142562719186147
1184975.156,1.99995036125183,20474.2813802083,90.0022506713867,0.143122727672259
1185015.046,1.99995104471842,22466.0899739583,90.0022506713867,0.143767028053602
1185055.031,1.99993052482605,24474.0145833333,90.0022506713867,0.144373456637065
1185094.953,1.99979952971141,26476.086328125,90.0022506713867,0.144713528951009
1185134.984,1.99981261094411,28464.658984375,90.0022506713867,0.145291353265444
1185174.921,1.99987916946411,30465.555859375,90.0022506713867,0.146160971124967
1185214.718,1.9998020251592,32469.0875,90.0022506713867,0.146786256631215
1185254.703,1.99922252496084,34468.6033854167,90.0022506713867,0.147541613380114
1185294.765,1.99930508931478,36471.11640625,90.0022506713867,0.148467901349068
1185334.609,1.99812604586283,38459.6677083333,90.0022506713867,0.148988769451777
1185374.5,1.99918718338013,40466.925,90.0022506713867,0.149417039752007
1185414.421,1.99879206816355,42476.91171875,90.0022506713867,0.14972364505132
1185454.578,1.99577373663584,44472.8182291667,90.0022506713867,0.149868229031563
1185494.359,2.00026401678721,46470.9796875,90.0022506713867,0.150348724921544
1185534.39,1.99891750017802,48462.5731770833,90.0022506713867,0.150334509213765
1185574.265,1.99911282857259,50470.10234375,90.0022506713867,0.150030467907588
1185614,1.99907314777374,52474.8611979167,90.0022506713867,0.150082301100095
1185653.671,1.99936657746633,54470.22265625,90.0022506713867,0.150167819857597
1185693.312,1.99941218694051,56470.6145833333,90.0022506713867,0.150331538915634
1185732.984,1.9977752606074,58487.8921875,90.0022506713867,0.150319295128187
1185774.531,1.99790830612183,59999.8432291667,90.0022506713867,0.150456458330154
1185891.64,1.99880846341451,58527.9921875,150.002243041992,0.152806137005488
1185931.89,1.99879155158997,56531.8971354167,150.002243041992,0.152745600541433
1185972.062,1.99872425397237,54534.6453125,150.002243041992,0.15283059378465
1186012.265,1.99898494084676,52525.7716145833,150.002243041992,0.152505709727605
1186052.484,1.9989599943161,50534.5072916667,150.002243041992,0.152257060011228
1186092.734,1.99897546768188,48532.3731770833,150.002243041992,0.152337637543678
1186132.984,1.99906051158905,46535.4265625,150.002243041992,0.151692095398903
1186173.171,1.99924514293671,44537.1609375,150.002243041992,0.151733722289403
1186213.421,1.99924397468567,42533.678125,150.002243041992,0.151380580663681
1186253.671,1.99765745798747,40533.7463541667,150.002243041992,0.150931332508723
1186293.968,1.99445452690125,38540.4315104167,150.002243041992,0.150113175312678
1186334.234,2.0019909620285,36541.1520833333,150.002243041992,0.149037167429924
1186374.421,1.99966510931651,34532.7135416667,150.002243041992,0.147269918521245
1186414.609,1.99904548327128,32533.171484375,150.002243041992,0.14481621781985
1186454.859,1.99964171250661,30528.7256510417,150.002243041992,0.141337050994237
1186495.093,1.99945902029673,28533.7701822917,150.002243041992,0.138659826914469
1186535.375,1.99753913084666,26527.2049479167,150.002243041992,0.136778242389361
1186575.671,2.00138035615285,24505.9858072917,150.002243041992,0.135544076561928
1186615.687,1.99987500508626,22529.3709635417,150.002243041992,0.134582673509916
1186655.718,1.99968993663788,20540.1360677083,150.002243041992,0.134107007582982
1186695.765,1.99981928666433,18542.9420572917,150.002243041992,0.133520844578743
1186735.859,1.9999009291331,16525.6208984375,150.002243041992,0.133480975031853
1186776.015,1.99973497390747,14520.0179036458,150.002243041992,0.133538454771042
1186816.156,1.99894601504008,12536.2881510417,150.002243041992,0.133031286795934
1186856.14,2.00347836017609,10533.5380208333,150.002243041992,0.133111461997032
1186896.265,2.0002033551534,8529.09368489583,150.002243041992,0.132975835601489
1186936.328,2.00029785633087,6529.26399739583,150.002243041992,0.1304180453221
1186976.312,2.01300644874573,4533.31106770833,150.002243041992,0.114924214283625
1187016.421,2.00018760363261,2532.06635742188,150.002243041992,0.0631552803019683
1187056.421,2.00122957229614,531.602648925781,150.002243041992,0.0123263099541267
1187173.828,2.00157697995504,441.035493977865,210.002243041992,0.0125653165703019
1187214.421,2.00044131278992,2471.15091145833,210.002243041992,0.0346779735138019
1187254.562,2.00032254854838,4484.9392578125,210.002243041992,0.0775096490979195
1187294.421,1.99703021844228,6493.7509765625,210.002243041992,0.0954470654328664
1187334.515,2.00057650407155,8470.873046875,210.002243041992,0.100198681652546
1187374.484,2.00063783327738,10467.3339192708,210.002243041992,0.103957472741604
1187414.531,2.01337475776672,12462.4641927083,210.002243041992,0.107223047316074
1187454.5,2.00025413036346,14473.181640625,210.002243041992,0.109777257343133
1187494.406,1.99957493146261,16476.7840494792,210.002243041992,0.113125710686048
1187534.328,2.0029527425766,18470.8233072917,210.002243041992,0.116431909799576
1187574.296,1.99999094804128,20472.6268229167,210.002243041992,0.119428856670856
1187614.203,2.00004615783691,22468.3986979167,210.002243041992,0.122921588023504
1187654.296,1.99899412790934,24475.5294270833,210.002243041992,0.127246224880219
1187694.046,2.00072928269704,26465.6955729167,210.002243041992,0.131815318266551
1187734.125,1.98375999927521,28483.33359375,210.002243041992,0.134636769692103
1187774.015,1.99993588924408,30491.9423177083,210.002243041992,0.139995643496513
1187813.89,1.99950881004333,32474.0708333333,210.002243041992,0.143318036198616
1187853.875,1.99954515298208,34485.8861979167,210.002243041992,0.14721441368262
1187893.734,1.99872417449951,36467.428125,210.002243041992,0.149272508422534
1187933.75,1.99684567451477,38472.0015625,210.002243041992,0.150882810354233
1187973.687,1.99608867963155,40486.5869791667,210.002243041992,0.152075357238452
1188013.843,2.00007490317027,42466.2020833333,210.002243041992,0.151961847146352
1188053.656,1.99970893065135,44473.4322916667,210.002243041992,0.152688853939374
1188093.437,1.99974184830983,46469.27421875,210.002243041992,0.152609627445539
1188133.484,1.99972408612569,48469.5481770833,210.002243041992,0.152517061432203
1188173.296,1.99713890552521,50473.0778645833,210.002243041992,0.152927568554878
1188213.171,1.99660652478536,52472.7588541667,210.002243041992,0.153072109818459
1188252.875,2.00020316441854,54510.83671875,210.002243041992,0.152897424499194
1188292.468,1.99980719089508,56462.7692708333,210.002243041992,0.153383068243663
1188332.218,1.99966693719228,58478.0408854167,210.002243041992,0.153753121693929
1188373.765,1.99937805334727,59999.8234375,210.002243041992,0.15330798625946
1188475.343,1.99955062866211,58532.3549479167,225.002243041992,0.153140203158061
1188515.546,1.99968530337016,56532.2921875,225.002243041992,0.153008583188057
1188555.765,1.99959818522135,54535.99296875,225.002243041992,0.15301509698232
1188596.125,1.99973432223002,52530.5005208333,225.002243041992,0.152664738893509
1188636.312,1.99602991739909,50543.1981770833,225.002243041992,0.15256929397583
1188676.656,1.9972371896108,48522.5338541667,225.002243041992,0.152351703246435
1188716.843,1.9997446457545,46526.1802083333,225.002243041992,0.152161010106405
1188756.953,1.99990498224894,44527.3658854167,225.002243041992,0.151847246289253
1188797.187,1.99974466959635,42537.41015625,225.002243041992,0.151935691634814
1188837.406,1.99977552890778,40537.8044270833,225.002243041992,0.151741953690847
1188877.609,1.99982922871908,38536.878125,225.002243041992,0.151492727796237
1188917.906,1.99991788069407,36532.6434895833,225.002243041992,0.151970010995865
1188958.078,2.00244023005168,34534.0916666667,225.002243041992,0.151794431606929
1188998.39,1.99616953531901,32532.579296875,225.002243041992,0.151220841209094
1189038.578,2.0000617980957,30534.768359375,225.002243041992,0.151305517554283
1189078.921,2.00003018379211,28531.1641927083,225.002243041992,0.151096213857333
1189119.093,1.99995214144389,26533.596484375,225.002243041992,0.150639568765958
1189159.375,2.00040283203125,24537.6640625,225.002243041992,0.150437850753466
1189199.328,2.00337766806285,22532.7920572917,225.002243041992,0.149462997913361
1189239.375,2.00087028344472,20532.6227864583,225.002243041992,0.146830183267593
1189279.468,1.9977282444636,18522.4486979167,225.002243041992,0.143959873914719
1189319.671,2.00031728744507,16540.0651041667,225.002243041992,0.13987166484197
1189359.765,2.00013870398204,14529.0810546875,225.002243041992,0.135470661520958
1189399.875,2.00031351248423,12527.0838541667,225.002243041992,0.129004581769307
1189439.843,1.99993379116058,10532.3427734375,225.002243041992,0.122921616832415
1189480.062,2.00009466807048,8534.20442708333,225.002243041992,0.115463475386302
1189520.046,2.00148822466532,6525.70992838542,225.002243041992,0.105653500556946
1189560.109,2.00050905545553,4530.45895182292,225.002243041992,0.0886040359735489
1189600.281,2.00098823706309,2526.56726888021,225.002243041992,0.0441845734914144
1189640.14,2.00057563781738,535.142911783854,225.002243041992,0.0135777022689581
1189751.781,2.00082120895386,442.691357421875,270.002258300781,0.0123422420273225
1189792.421,2.00082756678263,2471.48315429688,270.002258300781,0.0583630308508873
1189832.375,2.00088097254435,4471.26451822917,270.002258300781,0.110204276939233
1189872.484,2.00002352396647,6462.08170572917,270.002258300781,0.130067481597265
1189912.453,2.00021489461263,8472.5115234375,270.002258300781,0.136023554205894
1189952.437,2.00279438495636,10501.2828125,270.002258300781,0.138356774051984
1189992.5,2.0003138144811,12463.7460286458,270.002258300781,0.140437648693721
1190032.406,2.00093050003052,14471.1518880208,270.002258300781,0.141733162601789
1190072.437,2.00385413169861,16520.1443359375,270.002258300781,0.143117330471675
1190112.421,1.99958162307739,18466.4149739583,270.002258300781,0.14380962351958
1190152.265,1.99969621499379,20472.6178385417,270.002258300781,0.144730758666992
1190192.078,1.99909403324127,22467.3419270833,270.002258300781,0.146019603808721
1190232.078,2.00016982555389,24466.2401041667,270.002258300781,0.146606526772181
1190272.046,2.00031957626343,26469.01640625,270.002258300781,0.147153168916702
1190311.968,1.99852315584819,28470.9505208333,270.002258300781,0.147944256663322
1190351.906,2.00081377824148,30471.8696614583,270.002258300781,0.148221057653427
1190391.843,1.98412302335103,32485.7125,270.002258300781,0.14923810561498
1190431.875,1.99937913417816,34463.5294270833,270.002258300781,0.149354257186254
1190471.703,2.00023566087087,36478.3877604167,270.002258300781,0.150214937329292
1190511.734,2.00017174084981,38469.2856770833,270.002258300781,0.150383968154589
1190551.796,2.0087779601415,40464.2046875,270.002258300781,0.150786754488945
1190591.593,1.99993592103322,42478.8299479167,270.002258300781,0.150555623571078
1190631.515,1.99883979956309,44468.8791666667,270.002258300781,0.15102244913578
1190671.421,1.99960312843323,46467.8924479167,270.002258300781,0.151143348217011
1190711.437,2.00024847189585,48482.5578125,270.002258300781,0.151377421617508
1190751.296,2.00038714408875,50471.46171875,270.002258300781,0.151528445879618
1190791.171,2.00041143099467,52475.0697916667,270.002258300781,0.151570075750351
1190830.796,2.00046639442444,54473.8307291667,270.002258300781,0.15206928451856
1190870.437,1.99708759784698,56470.4755208333,270.002258300781,0.151494458317757
1190910.109,1.99739071528117,58464.97265625,270.002258300781,0.151558057467143
1190951.546,2.00008889834086,59999.8161458333,270.002258300781,0.151991679271062
1191068.546,1.99923259417216,58529.45859375,330.002258300781,0.150277145703634
1191108.796,1.99916800657908,56542.2953125,330.002258300781,0.150491080681483
1191148.984,1.99927302201589,54531.4861979167,330.002258300781,0.149962022900581
1191189.218,1.99949265321096,52528.1111979167,330.002258300781,0.150239959359169
1191229.406,1.99934728145599,50537.2763020833,330.002258300781,0.149896947542826
1191269.625,1.99933699766795,48532.8135416667,330.002258300781,0.149949822823207
1191309.828,1.99959168434143,46531.615625,330.002258300781,0.149892704685529
1191350.171,1.99751026630402,44539.6205729167,330.002258300781,0.149727166692416
1191390.468,1.99644388357798,42521.89140625,330.002258300781,0.149368798732758
1191430.656,1.99973302682241,40530.89140625,330.002258300781,0.149115597208341
1191470.812,1.99936455885569,38525.98203125,330.002258300781,0.148764857649803
1191511.046,1.99944095611572,36532.7203125,330.002258300781,0.148255507151286
1191551.25,1.99967795213064,34534.5458333333,330.002258300781,0.146912012497584
1191591.578,1.99960154692332,32529.6662760417,330.002258300781,0.144826270143191
1191631.812,2.00112308661143,30529.5016927083,330.002258300781,0.142993397514025
1191671.968,2.00037932395935,28534.4654947917,330.002258300781,0.140098732709885
1191712.218,1.99941934744517,26532.2483072917,330.002258300781,0.13749661842982
1191752.484,1.99965428511302,24526.7151041667,330.002258300781,0.135753527283669
1191792.406,1.99978181521098,22536.8087239583,330.002258300781,0.135166039069494
1191832.515,2.00006065368652,20527.3186197917,330.002258300781,0.134186101953189
1191872.625,2.00144253571828,18525.13203125,330.002258300781,0.133625916639964
1191912.734,1.99955432415009,16530.7794270833,330.002258300781,0.133221435546875
1191952.984,2.00333521366119,14523.7809895833,330.002258300781,0.132956498861313
1191993.046,2.00022335847219,12530.7194010417,330.002258300781,0.132810681064924
1192033.218,2.00025273958842,10523.6885416667,330.002258300781,0.13284537990888
1192073.093,2.013503352801,8529.86966145833,330.002258300781,0.132875214020411
1192113.187,1.99996174971263,6534.88606770833,330.002258300781,0.130973998705546
1192153.281,2.0000448067983,4527.47223307292,330.002258300781,0.114634372790655
1192193.343,1.9997144540151,2540.53875325521,330.002258300781,0.0653047040104866
1192233.484,2.00239730676015,531.287554931641,330.002258300781,0.0125001439203819
1197873.703,1.99703200658162,438.789231363932,-0.004302978515625,0.0116641251991193
1197914.343,1.99718190034231,2467.91303710938,-0.004302978515625,0.0375035755336285
1197954.375,1.99749039014181,4458.98958333333,-0.004302978515625,0.0840192422270775
1197994.343,1.99751992225647,6468.03990885417,-0.004302978515625,0.120729352533817
1198034.468,1.99761056900024,8469.47994791667,-0.004302978515625,0.137098802129428
1198074.453,1.99761979579926,10473.5599609375,-0.004302978515625,0.144887165228526
1198114.515,1.99772686163584,12461.6134114583,-0.004302978515625,0.148626925547918
1198154.515,1.99776604970296,14472.6225911458,-0.004302978515625,0.149301414688428
1198194.359,1.99780173301697,16472.2166666667,-0.004302978515625,0.149310971299807
1198234.328,1.99787178834279,18470.915234375,-0.004302978515625,0.149434286355972
1198274.25,1.99795373280843,20460.6528645833,-0.004302978515625,0.149412175019582
1198314.421,1.99801940917969,22479.09609375,-0.004302978515625,0.149209822217623
1198354.156,1.99824754397074,24472.5944010417,-0.004302978515625,0.149227521816889
1198394.125,1.99826140403748,26474.7096354167,-0.004302978515625,0.149583187699318
1198434.156,1.9983814795812,28463.2596354167,-0.004302978515625,0.149485218524933
1198475.968,1.99802538553874,29999.7649739583,-0.004302978515625,0.149536568919818
1198578.39,1.99828224182129,28524.471875,15.0023431777954,0.14941072066625
1198618.546,1.99843985239665,26532.243359375,15.0023431777954,0.149237656593323
1198658.781,1.99854156176249,24534.0962239583,15.0023431777954,0.149473798274994
1198698.906,1.99870842297872,22539.6016927083,15.0023431777954,0.149496698379517
1198738.875,1.99877038002014,20534.434765625,15.0023431777954,0.148975106080373
1198779.093,1.99881525039673,18529.96484375,15.0023431777954,0.148481205105782
1198819.203,1.99898636341095,16524.328515625,15.0023431777954,0.146409859259923
1198859.343,1.99914402167002,14535.3049479167,15.0023431777954,0.143005722761154
1198899.328,1.99922246932983,12542.6397786458,15.0023431777954,0.138479854663213
1198939.359,1.99937249819438,10530.9391276042,15.0023431777954,0.132664895057678
1198979.515,1.99944932460785,8543.4546875,15.0023431777954,0.123656302193801
1199019.515,1.99964172840118,6539.93561197917,15.0023431777954,0.10892640799284
1199059.562,1.99979707400004,4534.78082682292,15.0023431777954,0.0791609595219294
1199099.687,1.99996661345164,2538.49840494792,15.0023431777954,0.0329185627400875
1199139.828,2.00072855949402,535.68486328125,15.0023431777954,0.0124429503455758
1199250.812,2.00048305193583,448.390380859375,60.0023384094238,0.0128554366528988
1199291.281,2.00031859079997,2469.78430989583,60.0023384094238,0.0550352074205875
1199331.296,2.0003916422526,4467.2556640625,60.0023384094238,0.105802043775717
1199371.265,2.00037535031637,6482.00234375,60.0023384094238,0.126882648468018
1199411.406,2.00027046203613,8468.76868489583,60.0023384094238,0.138108504811923
1199451.359,2.00014314651489,10468.8671223958,60.0023384094238,0.144992310802142
1199491.359,2.00011870861053,12468.9380859375,60.0023384094238,0.148780836661657
1199531.421,1.99992394447327,14472.0057942708,60.0023384094238,0.149258134762446
1199571.328,1.99985615412394,16471.2563802083,60.0023384094238,0.149522175391515
1199611.109,1.99973253409068,18464.2486979167,60.0023384094238,0.149501180648804
1199651.265,1.99968914190928,20472.0553385417,60.0023384094238,0.149595885475477
1199691.031,1.99962611198425,22464.4755208333,60.0023384094238,0.149557627240817
1199731.171,1.99957056045532,24463.2889322917,60.0023384094238,0.149364596605301
1199770.921,1.99944729804993,26464.4817708333,60.0023384094238,0.149397739768028
1199810.937,1.99946614106496,28472.715234375,60.0023384094238,0.149229574203491
1199852.859,1.99913872083028,29999.7825520833,60.0023384094238,0.149562441309293
1199955.312,1.99931791623433,28533.34140625,75.0023422241211,0.149596776564916
1199995.609,1.99925550619761,26541.7661458333,75.0023422241211,0.149876508116722
1200035.734,1.99931708176931,24528.654296875,75.0023422241211,0.149776511391004
1200075.921,1.99939098358154,22530.5235677083,75.0023422241211,0.149466287096341
1200116.078,1.99935948053996,20540.029296875,75.0023422241211,0.14965404967467
1200156.14,1.9994900226593,18538.830078125,75.0023422241211,0.149096196889877
1200196.234,1.99951033592224,16516.5365885417,75.0023422241211,0.148609045147896
1200236.218,1.99953925609589,14528.8709635417,75.0023422241211,0.147891932725906
1200276.39,1.99959583282471,12529.8857421875,75.0023422241211,0.146456255515416
1200316.437,1.99971808592478,10540.1430338542,75.0023422241211,0.145087070266406
1200356.515,1.99985148906708,8522.72005208333,75.0023422241211,0.142423544327418
1200396.578,1.99993000825246,6529.8439453125,75.0023422241211,0.13370457192262
1200436.578,2.00004970232646,4534.93994140625,75.0023422241211,0.115098855396112
1200476.703,2.00032588640849,2539.39262695312,75.0023422241211,0.0594736208518346
1200516.734,2.00099391937256,527.926631673177,75.0023422241211,0.012822808449467
1200621.984,2.00070669651031,446.962829589844,105.002342224121,0.0125193189829588
1200662.5,2.00062058766683,2469.40851236979,105.002342224121,0.064903266231219
1200702.625,2.0006316502889,4476.54583333333,105.002342224121,0.117090199391047
1200742.453,2.00060973167419,6472.96748046875,105.002342224121,0.137976823250453
1200782.687,2.00053065617879,8464.72428385417,105.002342224121,0.141987040638924
1200822.531,2.00041117668152,10467.8715494792,105.002342224121,0.143983033299446
1200862.718,2.00026568571726,12478.2159505208,105.002342224121,0.145937913656235
1200902.609,2.00023746490479,14470.9298177083,105.002342224121,0.147139052549998
1200942.484,2.00015037854513,16469.2455078125,105.002342224121,0.148171492417653
1200982.453,2.00000243186951,18468.917578125,105.002342224121,0.149041104316711
1201022.406,1.99997183481852,20461.9998697917,105.002342224121,0.149244205156962
1201062.218,1.99986583391825,22463.7700520833,105.002342224121,0.149498094121615
1201102.343,2.00016252994537,24463.6635416667,105.002342224121,0.149654682477315
1201142.218,1.99961459636688,26468.10546875,105.002342224121,0.150323395927747
1201182.218,1.99926254749298,28472.660546875,105.002342224121,0.150486582517624
1201223.906,1.9983337799708,29999.78515625,105.002342224121,0.150119744737943
1201325.593,1.99845350583394,28532.7921875,120.002342224121,0.150770384073257
1201365.859,1.99814012050629,26527.95234375,120.002342224121,0.150571886698405
1201406.015,1.99860277175903,24532.419140625,120.002342224121,0.15013764500618
1201446.25,1.9986819823583,22519.2524739583,120.002342224121,0.150313369433085
1201486.14,1.99909240404765,20531.7723958333,120.002342224121,0.150389066338539
1201526.296,1.9994477669398,18531.278515625,120.002342224121,0.150083204110463
1201566.328,1.99859771728516,16527.9048177083,120.002342224121,0.150023938218753
1201606.578,2.00688552061717,14519.6845052083,120.002342224121,0.149849929412206
1201646.593,1.99948407014211,12529.3158854167,120.002342224121,0.149038125077883
1201686.546,1.99931379159292,10533.2335286458,120.002342224121,0.147746858994166
1201726.671,1.99936957359314,8536.75611979167,120.002342224121,0.144510181744893
1201766.734,1.9965976079305,6524.30345052083,120.002342224121,0.13742371002833
1201807.046,1.99957325458527,4520.07708333333,120.002342224121,0.118162036935488
1201846.89,1.99960338274638,2532.81520182292,120.002342224121,0.0718009303013484
1201886.89,2.00060118039449,533.345485432943,120.002342224121,0.0132272065927585
1201987.859,2.00275202592214,446.727298990885,135.002349853516,0.0133789005999764
1202028.515,2.00023731390635,2463.83675130208,135.002349853516,0.0696989804506302
1202068.406,2.00022222995758,4465.95384114583,135.002349853516,0.117448437710603
1202108.437,1.99946804841359,6467.77981770833,135.002349853516,0.131346402565638
1202148.546,2.00064293543498,8470.50338541667,135.002349853516,0.135724649826686
1202188.453,2.00064228375753,10467.9266927083,135.002349853516,0.141102416316668
1202228.593,2.01535851955414,12472.0274739583,135.002349853516,0.145544972022374
1202268.468,1.99973891576131,14467.0370442708,135.002349853516,0.147278116146723
1202308.421,1.99964104493459,16466.6533854167,135.002349853516,0.148837440212568
1202348.437,2.00010724862417,18472.3243489583,135.002349853516,0.149317119518916
1202388.39,1.99978223641713,20463.8100260417,135.002349853516,0.149874106049538
1202428.187,1.99974043369293,22465.2856770833,135.002349853516,0.149937174717585
1202468.187,2.01328935623169,24471.1118489583,135.002349853516,0.150082623958588
1202508.218,1.99962696234385,26463.54296875,135.002349853516,0.150412479043007
1202548.203,1.99763820171356,28478.7787760417,135.002349853516,0.150866760810216
1202589.828,1.99898273944855,29999.75703125,135.002349853516,0.150748468438784
1202696.484,1.99901406764984,28531.2989583333,165.002349853516,0.151037183403969
1202736.687,1.99937238693237,26532.7700520833,165.002349853516,0.151008867224058
1202776.843,1.99991487661997,24533.93828125,165.002349853516,0.150293979048729
1202817.156,1.99734040896098,22537.7484375,165.002349853516,0.150486666957537
1202857.046,1.99877263704936,20534.2591145833,165.002349853516,0.149601149559021
1202897.171,1.99986310799917,18534.7555989583,165.002349853516,0.148311177889506
1202937.296,1.99984374046326,16528.0921223958,165.002349853516,0.146937652428945
1202977.39,1.99963180224101,14528.4880859375,165.002349853516,0.143791777888934
1203017.406,1.99891918500264,12533.4474609375,165.002349853516,0.139347985386848
1203057.531,1.99967903296153,10534.0578125,165.002349853516,0.135563440124194
1203097.562,1.99999535878499,8547.25872395833,165.002349853516,0.133689553538958
1203137.671,1.99998760223389,6534.45862630208,165.002349853516,0.126856034994125
1203177.765,2.00054251352946,4528.22737630208,165.002349853516,0.105099920928478
1203217.703,2.00466089248657,2536.74189453125,165.002349853516,0.0552880970140298
1203257.843,2.00102066993713,532.475895182292,165.002349853516,0.0125578705842296
1203358.843,2.00119723478953,449.038661702474,180.002349853516,0.011783338089784
1203399.343,2.00098072687785,2475.0767578125,180.002349853516,0.0404362375537554
1203439.281,2.00096273422241,4466.16956380208,180.002349853516,0.087805567185084
1203479.281,2.00062847137451,6464.36848958333,180.002349853516,0.121506720781326
1203519.421,2.00024222532908,8477.42434895833,180.002349853516,0.139107718070348
1203559.562,1.99950030644735,10485.5070963542,180.002349853516,0.147129693627357
1203599.468,2.00027398268382,12470.265234375,180.002349853516,0.149376049637794
1203639.468,2.00022424062093,14463.9909505208,180.002349853516,0.149969609578451
1203679.328,2.01500293413798,16469.25625,180.002349853516,0.150586003065109
1203719.296,2.00012203057607,18472.6162760417,180.002349853516,0.150647930304209
1203759.328,2.00105992158254,20474.7458333333,180.002349853516,0.150881996750832
1203799.156,1.99714000225067,22459.159765625,180.002349853516,0.151204253236453
1203839.093,1.99973660310109,24470.68125,180.002349853516,0.151159337162972
1203879.031,1.99996931552887,26473.137890625,180.002349853516,0.151068449020386
1203919.078,1.99981322288513,28481.0611979167,180.002349853516,0.151302831371625
1203960.75,1.99827248255412,29999.8037760417,180.002349853516,0.151418024301529
1204062.5,1.99960009256999,28534.01484375,195.002349853516,0.151566541194916
1204102.734,1.99937664667765,26517.6055989583,195.002349853516,0.151427448789279
1204142.89,1.99962686697642,24535.67265625,195.002349853516,0.15111021399498
1204183.046,1.99974375565847,22531.8881510417,195.002349853516,0.150956678390503
1204223.125,1.99971551100413,20530.7296875,195.002349853516,0.150883787870407
1204263.187,1.99995411237081,18530.565234375,195.002349853516,0.150354612867037
1204303.328,1.99929409821828,16527.8912109375,195.002349853516,0.148622617125511
1204343.578,1.99984777768453,14530.8989583333,195.002349853516,0.145253330469131
1204383.515,1.99987816015879,12528.5992838542,195.002349853516,0.141063588857651
1204423.578,2.00001441637675,10525.1862630208,195.002349853516,0.134971259037654
1204463.625,1.99946825504303,8530.051953125,195.002349853516,0.125811724364758
1204503.625,1.99988849163055,6535.18782552083,195.002349853516,0.110604933897654
1204543.875,2.00140416622162,4526.35061848958,195.002349853516,0.0786233196655909
1204583.796,2.00047095616659,2542.05797526042,195.002349853516,0.0327461102356513
1204624.093,2.00144309997559,527.931528727214,195.002349853516,0.0125179175287485
1204734.781,2.00028942426046,447.36216023763,240.002349853516,0.0129632333293557
1204775.343,1.99871906439463,2470.13701171875,240.002349853516,0.0540732637047768
1204815.328,2.00086161295573,4466.62477213542,240.002349853516,0.103774224221706
1204855.39,2.00046498775482,6466.08642578125,240.002349853516,0.125099653502305
1204895.437,2.00318586826324,8475.8013671875,240.002349853516,0.137804642319679
1204935.484,2.00016881624858,10462.2544921875,240.002349853516,0.144817937413851
1204975.515,1.9999000787735,12460.3599609375,240.002349853516,0.149092841148376
1205015.484,2.00065654118856,14471.3451822917,240.002349853516,0.150226330757141
1205055.375,2.00009044011434,16480.0035807292,240.002349853516,0.150497217973073
1205095.312,2.00039142767588,18468.9578125,240.002349853516,0.150796804825465
1205135.281,2.00165936946869,20470.4243489583,240.002349853516,0.150560960173607
1205175.234,2.00166056950887,22458.8696614583,240.002349853516,0.150540858507156
1205215.234,1.99096469084422,24485.1122395833,240.002349853516,0.151346404353778
1205255.125,1.99993325074514,26463.186328125,240.002349853516,0.150986015796661
1205295.015,1.99962549209595,28477.1123697917,240.002349853516,0.151337856054306
1205336.765,1.99965864022573,29999.8001302083,240.002349853516,0.151043653488159
1205438.609,2.00030528704325,28536.5756510417,255.002349853516,0.150937759876251
1205478.828,1.99909465312958,26531.9993489583,255.002349853516,0.150829801956813
1205519,1.99946924050649,24534.5489583333,255.002349853516,0.150494685769081
1205559.296,1.99943339824677,22534.03515625,255.002349853516,0.150346145033836
1205599.281,1.99969178040822,20521.2442708333,255.002349853516,0.150528345505397
1205639.359,1.99548590977987,18541.3770833333,255.002349853516,0.150033973654111
1205679.406,1.99909842809041,16532.3827473958,255.002349853516,0.149323383967082
1205719.64,1.99258708159129,14524.4279296875,255.002349853516,0.148371835549672
1205759.718,1.99966639677684,12535.7326822917,255.002349853516,0.147599544127782
1205799.687,1.99996200402578,10521.4084635417,255.002349853516,0.144930595159531
1205839.671,2.00015333493551,8539.2396484375,255.002349853516,0.142075313131015
1205879.812,1.99905058542887,6532.7357421875,255.002349853516,0.133147897322973
1205919.937,1.99997833569845,4537.157421875,255.002349853516,0.113739661375682
1205959.984,1.98952810764313,2514.29357096354,255.002349853516,0.0562159975369771
1206000.109,2.00117292404175,526.443975830078,255.002349853516,0.0128524973988533
1206105.921,1.99944937229156,446.734670003255,285.002349853516,0.0123550657803814
1206146.562,2.00037275950114,2475.47543945313,285.002349853516,0.0631448822716872
1206186.64,1.98134326140086,4479.923828125,285.002349853516,0.113484157621861
1206226.484,2.00038839181264,6465.3888671875,285.002349853516,0.136921275655429
1206266.578,2.00065484046936,8474.46666666667,285.002349853516,0.142481676737467
1206306.546,2.00043416817983,10460.302734375,285.002349853516,0.144175016880035
1206346.578,2.00082166194916,12471.0234375,285.002349853516,0.146205085515976
1206386.546,1.99969059626261,14471.7423177083,285.002349853516,0.147232369581858
1206426.531,1.99835367202759,16491.3450520833,285.002349853516,0.148114200433095
1206466.328,2.0001090447108,18464.682421875,285.002349853516,0.148572037617366
1206506.343,2.00011456012726,20470.1540364583,285.002349853516,0.149439350763957
1206546.296,2.0062700510025,22468.5739583333,285.002349853516,0.149331565697988
1206586.203,2.00049644311269,24468.400390625,285.002349853516,0.149766926964124
1206626.25,2.00400413672129,26469.4984375,285.002349853516,0.150389688213666
1206666.234,1.99852192401886,28473.75390625,285.002349853516,0.149833644429843
1206707.937,1.99949560960134,29999.7908854167,285.002349853516,0.150323294599851
1206809.5,2.00050682226817,28529.4010416667,300.002349853516,0.15012790064017
1206849.703,1.99802267551422,26521.9385416667,300.002349853516,0.15006857017676
1206889.937,1.99665717283885,24530.3803385417,300.002349853516,0.150065110127131
1206929.953,1.99911682605743,22540.86015625,300.002349853516,0.150152868032455
1206970.031,1.99952226479848,20529.3998697917,300.002349853516,0.150071362654368
1207010.078,1.99988918304443,18532.5686197917,300.002349853516,0.149897654851278
1207050.203,1.99971566200256,16533.1952473958,300.002349853516,0.149733410278956
1207090.312,1.99976069927216,14529.5948567708,300.002349853516,0.149463292956352
1207130.5,2.00001465479533,12528.5828125,300.002349853516,0.148752121130625
1207170.421,2.00051299730937,10545.485546875,300.002349853516,0.147688653071721
1207210.703,2.00002612272898,8528.07727864583,300.002349853516,0.144784892598788
1207250.828,2.0001478433609,6515.58264973958,300.002349853516,0.138112977147102
1207290.75,1.99464162985484,4525.0501953125,300.002349853516,0.116519693036874
1207330.703,2.00024573008219,2533.6873046875,300.002349853516,0.0693954656521479
1207370.796,2.00091071128845,529.246997070313,300.002349853516,0.0131075100973248
1207473.703,2.00063138802846,455.269156901042,315.002349853516,0.0133863541608055
1207514.171,2.0026669104894,2464.35922851563,315.002349853516,0.068098213771979
1207554.078,2.00040752092997,4465.83444010417,315.002349853516,0.118139427403609
1207594.078,2.00021528402964,6464.90110677083,315.002349853516,0.131684479117394
1207634.281,2.00139820575714,8466.34850260417,315.002349853516,0.136531233787537
1207674.171,2.00047165552775,10470.78515625,315.002349853516,0.141962571938833
1207714.328,2.00057295958201,12460.5447265625,315.002349853516,0.145841785271962
1207754.296,1.99791815280914,14479.9186197917,315.002349853516,0.147682574391365
1207794.062,1.99978296756744,16469.8041666667,315.002349853516,0.148820737997691
1207834.078,1.98478731314341,18488.1950520833,315.002349853516,0.148985479275386
1207873.984,1.99962793191274,20471.30546875,315.002349853516,0.149173661073049
1207913.89,1.99999946753184,22472.0947916667,315.002349853516,0.149278208613396
1207953.906,2.00043487548828,24471.2740885417,315.002349853516,0.149603781104088
1207993.828,2.00146522521973,26471.3819010417,315.002349853516,0.149795407056808
1208033.796,2.0030930519104,28466.9791666667,315.002349853516,0.15004731019338
1208075.375,1.99509715239207,29999.7763020833,315.002349853516,0.149983234206835