File: export_angle_-5_330deg_2p1K_4000oe.dat
Time Stamp (sec),Temperature (K),Magnetic Field (Oe),Sample Position (degrees),Bridge 1 Resistance (Ohms)
1001130.875,2.09764490127563,3999.87412109375,-4.99335432052612,0.0947202271223068
1001150.671,2.09786500930786,3999.8634765625,-2.0079824924469,0.0933156365156174
1001170.984,2.09814896583557,3999.8779296875,0.984038352966309,0.0900741612911224
1001191.281,2.09813243865967,3999.8701953125,3.97605919837952,0.0877342811226845
1001211.078,2.09838448524475,3999.8475,6.96143102645874,0.0855107009410858
1001231.453,2.09820302009583,3999.8576953125,9.95345211029053,0.0842462563514709
1001251.812,2.0985186958313,3999.859609375,12.9454736709595,0.0837748751044273
1001271.765,2.09854641914368,3999.8794921875,15.9374952316284,0.0837096232175827
1001291.921,2.098579454422,3999.8765234375,18.9228687286377,0.0825910964608192
1001312.203,2.09861193656921,3999.86348632813,21.9148902893066,0.0800586840510368
1001332.062,2.09865640640259,3999.86155273438,24.9069118499756,0.0801738661527634
1001351.781,2.09879608154297,3999.866875,27.8922843933105,0.0802985307574272
1001372.406,2.09872685432434,3999.86541992187,30.8843059539795,0.081004204750061
1001392.64,2.09881769180298,3999.85236328125,33.8763275146484,0.0822592371702194
1001412.562,2.0988521194458,3999.85712890625,36.868350982666,0.0854394736886024
1001432.453,2.0989574432373,3999.85865234375,39.8537254333496,0.0883804231882095
1001452.359,2.09883645057678,3999.84654296875,42.8457489013672,0.0911209565401077
1001472.343,2.09885676383972,3999.83833984375,45.8377723693848,0.0953085985779762
1001492.781,2.09881888389587,3999.8363671875,48.8297958374023,0.0977591568231583
1001512.968,2.09882647514343,3999.84310546875,51.8151702880859,0.100849201977253
1001532.734,2.09880229949951,3999.86056640625,54.8071937561035,0.104486106038094
1001552.921,2.09887261390686,3999.82955078125,57.7992172241211,0.107543286681175
1001573.062,2.09890955924988,4000.06935546875,60.7845916748047,0.110229504704475
1001593.125,2.09901000022888,3999.83244140625,63.7766151428223,0.112414037287235
1001612.906,2.09904764175415,3999.85966796875,66.7686386108398,0.114944498836994
1001633.218,2.0990867805481,3999.84265625,69.7606658935547,0.116953178048134
1001653.296,2.09892715454102,3999.85431640625,72.7460403442383,0.118034421205521
1001673.234,2.09901196479797,3999.86202148438,75.7380676269531,0.118569633364677
1001693.609,2.09900159835815,3999.84895507813,78.730094909668,0.118015220165253
1001713.39,2.09926626205444,3999.8436328125,81.7221221923828,0.117030936479568
1001733.14,2.09915369987488,3999.85333984375,84.7074966430664,0.115753791928291
1001753.171,2.0990082359314,3999.8490234375,87.6995239257813,0.114913076460361
1001773.281,2.09905963897705,3999.8402734375,90.6915512084961,0.114133266210556
1001794.312,2.09913754463196,3999.84416015625,93.6769256591797,0.113399607241154
1001813.796,2.0991153049469,3999.84748046875,96.6689529418945,0.114787682592869
1001833.593,2.09909032821655,3999.84220703125,99.6609802246094,0.117157200872898
1001853.531,2.09927724838257,3999.83783203125,102.653007507324,0.11965627849102
1001873.796,2.09912348747253,3999.8363671875,105.638381958008,0.121335815787315
1001894.062,2.09926337242126,3999.8504296875,108.630409240723,0.122074398994446
1001913.953,2.09943819046021,3999.99184570312,111.622436523438,0.122027409374714
1001934.343,2.09929606437683,3999.99958984375,114.614463806152,0.121802469789982
1001954.296,2.0994017791748,4000.00490234375,117.599838256836,0.121146310269833
1001974.703,2.09957084655762,3999.99573242187,120.591865539551,0.12099760144949
1001994.625,2.09952312469482,3999.98893554687,123.583892822266,0.120410190522671
1002014.656,2.09933693885803,3999.99086914062,126.569267272949,0.120244256258011
1002034.25,2.09968056678772,3999.98698242187,129.561294555664,0.11982605099678
1002053.953,2.09936809539795,3999.98216796875,132.553329467773,0.119419274032116
1002074.062,2.09966336250305,3999.98749023437,135.545364379883,0.119723532795906
1002093.921,2.09959184646606,3999.97780273438,138.530746459961,0.119870235323906
1002113.5,2.09975739479065,3999.975390625,141.52278137207,0.119536083936691
1002133.359,2.09965600967407,3999.97149414063,144.51481628418,0.118979462385178
1002153.484,2.09966156959534,3999.97537109375,147.500198364258,0.117922703623772
1002173.718,2.09955793380737,3999.98505859375,150.492233276367,0.11686589807272
1002193.984,2.09964829444885,3999.98119140625,153.484268188477,0.115431445240974
1002214.109,2.09989498138428,3999.99524414062,156.476303100586,0.114004225730896
1002233.875,2.09995554924011,3999.97974609375,159.461685180664,0.112171087563038
1002253.593,2.09966175079346,3999.966640625,162.453720092773,0.110239239931107
1002273.953,2.0998705291748,3999.9821875,165.445755004883,0.107640517652035
1002294.39,2.10003070831299,3999.9583984375,168.437789916992,0.105310310125351
1002314.781,2.1000333404541,3999.956953125,171.42317199707,0.102234641909599
1002334.828,2.09990390777588,3999.96616210938,174.41520690918,0.098899253308773
1002354.546,2.10024904251099,3999.9821484375,177.407241821289,0.0961313658952713
1002374.375,2.10007004737854,3999.97489257813,180.392623901367,0.0924436867237091
1002394.593,2.09996750831604,4000.01995117188,183.384658813477,0.0900915893912315
1002414.546,2.09994495391846,3999.995234375,186.376693725586,0.0871181589365005
1002434.921,2.10007054328918,3999.98551757812,189.368728637695,0.0855229753255844
1002454.921,2.10010047912598,3999.99767578125,192.354110717773,0.0843491351604462
1002475.046,2.10036154747009,3999.956484375,195.346145629883,0.0839494276046753
1002495.078,2.09990628242493,3999.97731445313,198.338180541992,0.0835232162475586
1002515.343,2.09999869346619,3999.9821484375,201.32356262207,0.0821573492884636
1002534.812,2.09987522125244,3999.98068359375,204.31559753418,0.0805988442897797
1002554.64,2.09982822418213,3999.97053710938,207.307632446289,0.0800197416543961
1002574.375,2.10004342079163,3999.98991210937,210.299667358398,0.0804576456546783
1002594.796,2.1000226020813,4000.28196289063,213.285049438477,0.0807731944322586
1002615.015,2.0997393321991,3999.8537890625,216.277084350586,0.0833227005600929
1002635.281,2.09967555999756,3999.8383203125,219.269119262695,0.0861083698272705
1002655.484,2.09997345924377,3999.83205078125,222.261154174805,0.0888703161478043
1002675.531,2.10000212669373,3999.85383789063,225.246536254883,0.0924485248327255
1002695.375,2.10029485702515,3999.82767578125,228.238571166992,0.0957373163104057
1002715.718,2.10014779090881,3999.8334375,231.230606079102,0.0982683479785919
1002735.39,2.09972550392151,3999.83251953125,234.21598815918,0.101416019499302
1002755.171,2.10025852203369,3999.82134765625,237.208023071289,0.104347040951252
1002775.109,2.10048884391785,3999.8184375,240.200057983398,0.107834847569466
1002795.062,2.10034204483032,3999.8466015625,243.192092895508,0.11019143730402
1002815.296,2.09983581542969,3999.82861328125,246.177474975586,0.11241485118866
1002835.468,2.10050840377808,3999.836796875,249.169509887695,0.114558164179325
1002855.343,2.10019394874573,3999.82521484375,252.161544799805,0.116013667285442
1002875.109,2.10013476371765,3999.84654296875,255.153579711914,0.117332575321198
1002894.921,2.09997974395752,3999.8392578125,258.138977050781,0.117848179638386
1002914.875,2.10008887290955,3999.835390625,261.131011962891,0.117456156611443
1002934.89,2.10043553352356,3999.8276171875,264.123046875,0.116925694048405
1002955.156,2.10005374908447,3999.81458984375,267.108428955078,0.116200492680073
1002974.796,2.10072038650513,3999.82376953125,270.100463867188,0.115863077044487
1002994.578,2.10077430725098,3999.8208203125,273.092498779297,0.115618195533752
1003014.296,2.0998989200592,3999.8165234375,276.084533691406,0.116377831399441
1003034.328,2.10052306175232,3999.82912109375,279.069915771484,0.117637645304203
1003054.14,2.10030703544617,3999.8184375,282.061950683594,0.118034301400185
1003074.078,2.10031498908997,3999.81359375,285.053985595703,0.119832520186901
1003094.343,2.09970685958862,3999.81166015625,288.039367675781,0.120834369063377
1003114.75,2.10023294448853,3999.82283203125,291.031402587891,0.121090890467167
1003134.812,2.10039021492004,3999.80384765625,294.0234375,0.120315799713135
1003155.531,2.10040798187256,3999.83294921875,297.015472412109,0.119373098909855
1003175.562,2.09995953559875,3999.821796875,300.000854492188,0.118987720012665
1003372.421,2.09963185310364,3999.8325390625,299.994232177734,0.11917318880558
1003392.218,2.1005161190033,3999.8320703125,303.006225585938,0.119706469774246
1003412.453,2.10015233039856,3999.8212890625,306.004913330078,0.120304713845253
1003432.093,2.10110160827637,3999.81208984375,309.003601074219,0.120063172578812
1003452.046,2.10040884017944,3999.81501953125,312.002288818359,0.120073237717152
1003472.14,2.10045159339905,3999.8077734375,315.0009765625,0.120143759250641
1003492.906,2.100079164505,3999.84125,318.006317138672,0.120237876772881
1003512.812,2.10041243553162,3999.843671875,321.005004882813,0.119887760877609
1003533.25,2.10016516685486,3999.84171875,324.003692626953,0.119573084414005
1003552.984,2.09999346733093,3999.8475,327.002380371094,0.118516911566257
1003573.218,2.10049783706665,3999.820390625,330.001068115234,0.117380988001823