File: export_angle_-5_330deg_2p1K_3p1K_2000oe.dat
Time Stamp (sec),Temperature (K),Magnetic Field (Oe),Sample Position (degrees),Bridge 1 Resistance (Ohms)
1013704.234,2.29845189094543,1999.8656640625,-4.99672651290894,0.0759011206030846
1013724.5,2.29858829498291,1999.8782421875,-2.00470566749573,0.0734238159656525
1013744.203,2.29959941864014,1999.85162109375,0.98731517791748,0.0712953016161919
1013765.625,2.29940277099609,1999.79790039063,3.97933602333069,0.0682283493876457
1013785.375,2.29881324768066,1999.8308203125,6.96470785140991,0.0664952525496483
1013805.156,2.29937015533447,1999.83515625,9.9567289352417,0.0647046095132828
1013825.218,2.30511472702026,1999.861328125,12.9487504959106,0.0644769063591957
1013845.296,2.29989300727844,1999.88213867188,15.9407720565796,0.0620259803533554
1013865.39,2.29913159370422,1999.87000976562,18.9327945709229,0.0610208773612976
1013885.187,2.29909130096436,1999.89473632813,21.9248161315918,0.0605870026350021
1013905.328,2.29906882286072,1999.85987304688,24.9168376922607,0.0615711270272732
1013925.265,2.2991194152832,1999.8583984375,27.9022102355957,0.0622548978030682
1013945.125,2.29902985572815,1999.86860351563,30.8942317962646,0.063568172454834
1013965.156,2.2991227722168,1999.87439453125,33.8862533569336,0.0657667633891106
1013985.484,2.2923611831665,1999.8928125,36.8782768249512,0.0681891775131226
1014007.328,2.30012139320374,1999.8680859375,39.8703002929688,0.0726859933137894
1014027.156,2.2992634677887,1999.89280273438,42.8623237609863,0.0756204548478127
1014047.062,2.29957126617432,1999.88744628906,45.8543472290039,0.0783391758799553
1014066.843,2.30482623100281,1999.87829101563,48.8397216796875,0.0819278484582901
1014086.593,2.29929399490356,1999.88650390625,51.8317451477051,0.0843674218654633
1014106.296,2.29937429428101,1999.89422851562,54.8237686157227,0.0873855817317963
1014126.25,2.29926128387451,1999.87971679688,57.8157920837402,0.0898384633660316
1014146.468,2.29936183929443,1999.86420898438,60.8078155517578,0.0921674567461014
1014166.687,2.29941763877869,1999.89810546875,63.7998390197754,0.0943298894166946
1014186.625,2.29941640853882,1999.887890625,66.791862487793,0.0960537081956863
1014207.031,2.29941904067993,1999.88651367188,69.7772369384766,0.0973872727155685
1014227.015,2.29295190811157,1999.889375,72.7692642211914,0.0969325879216194
1014247.14,2.29710119247437,1999.89666015625,75.7612915039063,0.0994902756810188
1014267.406,2.29943339347839,2000.08306640625,78.7533187866211,0.100822495222092
1014287.109,2.29966534614563,2000.10196289062,81.7453460693359,0.101219756007195
1014307.25,2.31036951065063,1999.883125,84.7373733520508,0.103623340725899
1014327.25,2.29966138839722,1999.85645507813,87.7294006347656,0.101720342338085
1014347.109,2.29963544845581,1999.88405273438,90.7147750854492,0.101973993480206
1014367.39,2.29955948829651,1999.86083007813,93.7068023681641,0.101926277279854
1014387.234,2.29982006072998,1999.86857421875,96.6988296508789,0.102072175741196
1014407.265,2.2996199798584,1999.8656640625,99.6908569335938,0.101742706298828
1014427.609,2.29979025840759,1999.86857421875,102.682884216309,0.101590781211853
1014447.781,2.29993321418762,1999.85694335938,105.674911499023,0.101238797008991
1014468.25,2.2949716091156,1999.84,108.666938781738,0.100890620946884
1014489.687,2.30047950744629,1999.85694335938,111.652313232422,0.102254093885422
1014509.421,2.29951163291931,1999.84870117188,114.644340515137,0.102523340880871
1014529.328,2.29989882469177,1999.85549804688,117.636367797852,0.102909869253635
1014549.156,2.30985631942749,1999.85551757813,120.628395080566,0.104639602899551
1014569.593,2.2999739074707,1999.85017578125,123.620422363281,0.102779257297516
1014589.5,2.29959268569946,1999.8627734375,126.612449645996,0.102897450625896
1014609.875,2.29971965789795,1999.86419921875,129.604476928711,0.102604295015335
1014630.109,2.29968583106995,1999.86470703125,132.589859008789,0.10239239692688
1014649.89,2.30001181602478,1999.85986328125,135.581893920898,0.101729501187801
1014670.546,2.29962651252747,1999.8724609375,138.573928833008,0.10100838124752
1014691.046,2.29952422142029,1999.8850390625,141.565963745117,0.10043196439743
1014710.593,2.29401811599731,1999.875859375,144.557998657227,0.098192400932312
1014732.328,2.30140038490295,1999.87096679688,147.550033569336,0.0972465178370476
1014752.625,2.29945310592651,1999.87147460937,150.542068481445,0.0953204399347305
1014772.312,2.29995482444763,1999.84631835937,153.527450561523,0.0935282817482948
1014792.5,2.30808176040649,1999.87826171875,156.519485473633,0.0934674286842346
1014812.406,2.30204357147217,1999.87681640625,159.511520385742,0.0900593200325966
1014832.296,2.30002863883972,1999.87729492188,162.503555297852,0.0883103001117706
1014852.171,2.30032273292542,1999.88215820313,165.495590209961,0.0864526045322418
1014872.468,2.30036622047424,1999.86375,168.48762512207,0.0839770537614822
1014892.5,2.29992478370667,1999.88888671875,171.47966003418,0.0811554154753685
1014912.359,2.30024723052979,1999.887421875,174.465042114258,0.0784111812710762
1014932.343,2.30005680084229,1999.871484375,177.457077026367,0.0759587863087654
1014952.953,2.28853475570679,1999.86517578125,180.449111938477,0.0715806716680527
1014973.687,2.29994194984436,1999.8748828125,183.441146850586,0.0704800081253052
1014993.875,2.29993448257446,1999.876328125,186.433181762695,0.0674272862076759
1015013.796,2.30019968032837,1999.87583984375,189.425216674805,0.0651822143793106
1015033.312,2.30175639152527,1999.8748828125,192.417251586914,0.0648717373609543
1015053.265,2.30138872146606,1999.86907226562,195.402633666992,0.062997885197401
1015073.109,2.30032217025757,1999.87825195313,198.394668579102,0.0621009616553783
1015093.687,2.30032168388367,1999.8705078125,201.386703491211,0.0615516455471516
1015113.843,2.30016020774841,1999.8656640625,204.37873840332,0.0612840950489044
1015133.656,2.29976505279541,1999.88506835938,207.37077331543,0.0617105752229691
1015153.468,2.29998285293579,1999.87391601562,210.362808227539,0.0625201788544655
1015173.937,2.300096616745,1999.88262695313,213.354843139648,0.0637161380052566
1015193.765,2.28903891563416,1999.89809570312,216.340225219727,0.0644180473685265
1015214.125,2.29705177307129,1999.87970703125,219.332260131836,0.0698952335119247
1015233.937,2.30080933570862,1999.89521484375,222.324295043945,0.0728270542621613
1015254.281,2.30068554878235,1999.89084960938,225.316329956055,0.0761207282543182
1015274.281,2.30131143569946,1999.87922851563,228.308364868164,0.0795070099830627
1015294.625,2.29670163154602,1999.88264648438,231.300399780273,0.0818136873841286
1015314.437,2.30100351333618,1999.88890625,234.285781860352,0.0852692580223084
1015334.375,2.30022492408752,1999.86762695313,237.277816772461,0.0873101118206978
1015354.546,2.29984942436218,1999.86810546875,240.26985168457,0.0900136631727219
1015374.515,2.30027270317078,1999.89759765625,243.26188659668,0.0920280852913856
1015394.312,2.30013906478882,1999.87780273438,246.253921508789,0.0938933169841766
1015414.25,2.30000797271729,1999.8821484375,249.245956420898,0.0954600527882576
1015434.14,2.30013536453247,1999.88940429688,252.237991333008,0.0964072418212891
1015454.062,2.30275888442993,1999.8874609375,255.223373413086,0.0988968330621719
1015475.531,2.30091316223145,1999.87051757812,258.215423583984,0.0987583574652672
1015495.5,2.30046358108521,1999.8927734375,261.207458496094,0.0995557317137718
1015515.312,2.3008078956604,1999.89859375,264.199493408203,0.0998998308181763
1015535.671,2.30754235267639,1999.861796875,267.191528320313,0.101512996256351
1015555.296,2.3016854763031,1999.88213867188,270.183563232422,0.100817718505859
1015575.406,2.30084453582764,1999.88115234375,273.175598144531,0.100522052645683
1015595.671,2.30061503410339,1999.89280273438,276.160980224609,0.100447346866131
1015615.515,2.29990591049194,1999.95573242187,279.153015136719,0.10022849470377
1015635.25,2.30008414268494,2000.18380371094,282.145050048828,0.0999921646714211
1015655.156,2.30095182418823,2000.01965332031,285.137084960938,0.100000315904617
1015675.5,2.30008226394653,1999.89037597656,288.129119873047,0.100011629760265
1015695.781,2.2919994354248,1999.89036132813,291.121154785156,0.0981966862082481
1015716.171,2.29954816818237,1999.89666015625,294.113189697266,0.100669855773449
1015736.171,2.30081443786621,1999.89713867187,297.098571777344,0.101440534293652
1015756.453,2.30064436912537,1999.87002929687,300.090606689453,0.102248617708683
1015776.593,2.30985303878784,1999.86420898438,303.082641601563,0.104275424778461
1015796.406,2.29946556091309,1999.88072265625,306.074676513672,0.103198919892311
1015816.25,2.30089205741882,1999.8980859375,309.066711425781,0.10318219691515
1015836.593,2.30001148223877,2000.16830566406,312.058746337891,0.102408263981342
1015856.359,2.30022226333618,2000.18525878906,315.05078125,0.101892859339714
1015876.156,2.30008242607117,2000.05597167969,318.036163330078,0.101228082180023
1015895.984,2.30006814956665,1999.87874023438,321.028198242188,0.100505382418633
1015915.718,2.29980088233948,1999.87633789063,324.020233154297,0.0994732427597046
1015935.656,2.29387216567993,1999.87247070312,327.012268066406,0.0972620981931686
1015956.171,2.30208151817322,1999.87583984375,330.004302978516,0.0968308445811272
1016383.265,2.49978318214417,1999.90392578125,-5.00225830078125,0.116595565378666
1016403.015,2.49913190841675,1999.89423828125,-2.00358867645264,0.116007252335548
1016422.968,2.49929029464722,1999.83950195312,0.988432168960571,0.114947329461575
1016442.843,2.49920285224915,1999.82838867188,3.97380399703979,0.11398049145937
1016462.687,2.48897233963013,1999.83806640625,6.96582508087158,0.110743262469769
1016483.062,2.50019104003906,1999.84922851563,9.95784664154053,0.110288077890873
1016503.25,2.49941248893738,1999.88987304688,12.9498682022095,0.107518873810768
1016523.187,2.50008774757385,1999.89180664063,15.9418897628784,0.105670978724957
1016542.984,2.50587956428528,1999.881171875,18.9339122772217,0.105209014117718
1016562.921,2.50004305839539,1999.89227539062,21.9259338378906,0.10209649682045
1016582.765,2.49941746711731,1999.89376953125,24.9113063812256,0.0993154883384705
1016603.203,2.49942844390869,1999.8845703125,27.9033279418945,0.0989284986257553
1016623.437,2.49940823554993,1999.8869921875,30.8953495025635,0.0991502460837364
1016643.453,2.49943787574768,1999.88891601563,33.8873710632324,0.0999609899520874
1016663.859,2.49940641403198,1999.87969726563,36.87939453125,0.100779954195023
1016684.312,2.49950422286987,1999.8671484375,39.8714179992676,0.103406122028828
1016704.203,2.49943270683289,1999.86763671875,42.8634414672852,0.106399829089642
1016724.328,2.49511077880859,1999.8458203125,45.8488159179688,0.10944653570652
1016744.359,2.5004737663269,1999.86276367188,48.8408393859863,0.112988263368607
1016764.171,2.49997352600098,1999.87197265625,51.8328628540039,0.116164534389973
1016783.89,2.50027410507202,1999.86857421875,54.8248863220215,0.119607163071632
1016804.703,2.5094557762146,1999.86372070313,57.8169097900391,0.12333777487278
1016824.765,2.49851096153259,1999.87438476563,60.8089332580566,0.123666274249554
1016844.656,2.49941740989685,1999.86422851563,63.8009567260742,0.125737547874451
1016864.625,2.49946891784668,1999.87344726562,66.7863311767578,0.127035393118858
1016884.359,2.49955870628357,1999.86856933594,69.7783584594727,0.128408676981926
1016904.171,2.49971689224243,1999.88018554688,72.7703857421875,0.129304337501526
1016924.062,2.49975089073181,1999.8690625,75.7624130249023,0.130273651480675
1016943.984,2.49973066329956,1999.88795898438,78.7544403076172,0.130964086651802
1016964.25,2.49964943885803,1999.87924804688,81.746467590332,0.131551181077957
1016984.687,2.49127670288086,2000.1373046875,84.7384948730469,0.131477261185646
1017004.828,2.50257307052612,1999.87631835938,87.7238693237305,0.132348974943161
1017024.781,2.50019932746887,1999.86662109375,90.7158966064453,0.132799316048622
1017044.75,2.50017924308777,1999.87485351563,93.7079238891602,0.133132709264755
1017065.125,2.50947124481201,1999.86758789062,96.699951171875,0.134116384983063
1017085.14,2.49981098175049,1999.87099609375,99.6919784545898,0.133439195156097
1017104.968,2.49953246116638,1999.8690625,102.684005737305,0.133417146205902
1017124.796,2.49979953765869,1999.8951953125,105.67603302002,0.133549892306328
1017145.171,2.49949856758118,1999.89180664063,108.661407470703,0.133145594000816
1017165.296,2.49966047286987,1999.88455078125,111.653434753418,0.132931441664696
1017185.125,2.49960772514343,1999.87971679688,114.645462036133,0.132561097145081
1017204.968,2.49957802772522,1999.89760253906,117.637489318848,0.132192849516869
1017224.89,2.49976138114929,1999.8797265625,120.629516601563,0.131182932853699
1017244.89,2.49972045898437,1999.89471679687,123.621543884277,0.130399168729782
1017265.156,2.49962126731873,1999.89715820312,126.613571166992,0.129119676947594
1017285.546,2.49937434196472,1999.88844726563,129.59895324707,0.128464058637619
1017305.281,2.50011962890625,1999.88552734375,132.59098815918,0.127736696600914
1017325.171,2.50039468765259,1999.8990625,135.583023071289,0.127534124851227
1017344.921,2.49637795448303,1999.875390625,138.575057983398,0.126938578188419
1017364.89,2.50014904022217,1999.88166015625,141.567092895508,0.126537131071091
1017384.718,2.49980522155762,1999.88891601563,144.559127807617,0.126375615000725
1017405.062,2.4998869228363,1999.86858398437,147.551162719727,0.12609502017498
1017424.984,2.49996851921082,1999.87876953125,150.536544799805,0.125017984807491
1017445.203,2.49987378120422,1999.86956054687,153.528579711914,0.12422991424799
1017465,2.49994524002075,1999.87440429687,156.520614624023,0.123850053846836
1017485.031,2.49962332725525,1999.87775390625,159.512649536133,0.123139819800854
1017505.328,2.49956855773926,1999.87875976563,162.504684448242,0.122231330573559
1017525.609,2.50654417037964,1999.88889648438,165.496719360352,0.12141517996788
1017545.406,2.49964638710022,1999.86418945312,168.488754272461,0.119978272020817
1017565.75,2.50037753105164,1999.87000976562,171.474136352539,0.118853637576103
1017585.437,2.50041124343872,1999.891328125,174.466171264648,0.11777763068676
1017605.64,2.50158175468445,1999.8923046875,177.458206176758,0.116794928312302
1017625.468,2.49936806678772,1999.89228515625,180.450241088867,0.115450403988361
1017645.703,2.49954141616821,1999.88408691406,183.442276000977,0.114697512984276
1017665.625,2.49995278358459,1999.89713867187,186.434310913086,0.113705467283726
1017685.64,2.50013543128967,1999.90826171875,189.419692993164,0.111965148150921
1017705.39,2.50021838188171,1999.90920410156,192.411727905273,0.109398965239525
1017725.656,2.5001002407074,1999.89034179688,195.403762817383,0.107140995562077
1017745.453,2.50000290870666,1999.89086914063,198.395797729492,0.10509984433651
1017765.515,2.49973511695862,1999.89326171875,201.387832641602,0.103323176503181
1017785.875,2.49448190689087,1999.88502929688,204.379867553711,0.100977425277233
1017805.656,2.50048616409302,1999.85744140625,207.37190246582,0.0987184199690819
1017826.015,2.50054304122925,1999.88502929688,210.357284545898,0.0985121360421181
1017845.859,2.50079592704773,1999.89567382812,213.349319458008,0.0989344602823257
1017865.734,2.50721623420715,1999.88938476563,216.341354370117,0.10046701580286
1017885.765,2.49970532417297,1999.90102050781,219.333389282227,0.101547528207302
1017906.171,2.49980598449707,1999.89663574219,222.325424194336,0.103669322729111
1017926.687,2.49992824554443,1999.91118164063,225.317459106445,0.107820336222649
1017946.562,2.50033385276794,1999.90874023438,228.309494018555,0.110788904130459
1017966.375,2.50020768165588,1999.91937988281,231.294876098633,0.1133912935853
1017986.281,2.49986658096313,1999.91791992188,234.286911010742,0.116242588460445
1018007.312,2.4999383354187,1999.90680664063,237.278945922852,0.118807405531406
1018026.906,2.49963973045349,1999.8951953125,240.270980834961,0.121296578943729
1018047.203,2.49152598381042,1999.89905273437,243.26301574707,0.122353571653366
1018066.906,2.49887449264526,1999.8845703125,246.25505065918,0.125177882909775
1018087.187,2.50035496711731,1999.88599609375,249.247085571289,0.126988151669502
1018107.234,2.50067412376404,1999.898125,252.232467651367,0.12792229950428
1018127.328,2.50563239097595,1999.89375,255.224502563477,0.129241921305656
1018147.156,2.49943299293518,1999.89716796875,258.216552734375,0.129877169728279
1018167.625,2.5001312828064,1999.88260742188,261.208587646484,0.130531949996948
1018187.64,2.49983491897583,1999.90727539063,264.200622558594,0.130758920907974
1018207.453,2.49960496902466,1999.901015625,267.192657470703,0.131342766284943
1018227.765,2.49959187507629,1999.90243164063,270.184692382813,0.131624159812927
1018248.468,2.49975720405579,1999.8951953125,273.170074462891,0.132181796431541
1018268.703,2.49959990501404,1999.88747070313,276.162109375,0.132253504991531
1018288.953,2.49931169509888,1999.8671484375,279.154144287109,0.132493423819542
1018308.89,2.49409239768982,1999.88842773438,282.146179199219,0.131385977864265
1018328.765,2.49985200881958,1999.86758789062,285.138214111328,0.132753588557243
1018348.921,2.50061287879944,1999.8627734375,288.130249023438,0.13278513610363
1018368.921,2.50078842163086,1999.88842773438,291.122283935547,0.132639159560204
1018389.218,2.50761521339416,1999.89325195312,294.107666015625,0.13357416510582
1018409.75,2.50060376167297,1999.88067382813,297.099700927734,0.132411044239998
1018429.843,2.50050763130188,1999.8773046875,300.091735839844,0.132096756696701
1018449.578,2.50020493507385,1999.8700390625,303.083770751953,0.131334280371666
1018469.406,2.50020447731018,1999.8695703125,306.075805664063,0.130590022206306
1018490.187,2.49983784675598,1999.87923828125,309.067840576172,0.129290089607239
1018510.046,2.50032810211182,1999.86954101562,312.059875488281,0.128451731204987
1018530.109,2.50048824310303,1999.881171875,315.045257568359,0.127775992155075
1018550.14,2.50039216041565,1999.87243164063,318.037292480469,0.127387901544571
1018569.734,2.49373349189758,1999.89181640625,321.029327392578,0.126311664879322
1018589.89,2.49946939468384,1999.87244140625,324.021362304688,0.126529323458672
1018610.312,2.4999954032898,1999.867109375,327.013397216797,0.125971423983574
1018630.125,2.50073328971863,1999.8801953125,330.005432128906,0.125005288720131
1023674.437,2.69761702537537,1999.88696289063,-5.00112915039063,0.146308419704437
1023694.234,2.69719879150391,1999.87778320313,-2.00245952606201,0.146079606413841
1023715.031,2.69722666740417,1999.8879296875,0.982912302017212,0.145597290992737
1023734.812,2.69743251800537,1999.90535644531,3.97493314743042,0.144761075973511
1023754.515,2.69758706092834,1999.89181640625,6.96695423126221,0.143893142938614
1023774.281,2.69763582229614,1999.8932421875,9.95897579193115,0.142389075160027
1023794.562,2.69770564079285,1999.89473632813,12.9509973526001,0.140359546542168
1023814.281,2.69796298027039,1999.87295898437,15.943018913269,0.137950119376183
1023834.421,2.69802772521973,1999.87294921875,18.9350414276123,0.134688901305199
1023854.125,2.6979955291748,1999.88309570313,21.9204139709473,0.12931893825531
1023873.875,2.69817786216736,1999.900546875,24.9124355316162,0.125759169757366
1023893.968,2.69819796562195,1999.9019921875,27.9044570922852,0.121984768211842
1023913.765,2.69821575164795,1999.8976171875,30.8964786529541,0.12034257620573
1023933.468,2.69835925102234,1999.88552734375,33.888500213623,0.12172620922327
1023953.5,2.69831176757813,1999.8841015625,36.8805236816406,0.123599973022938
1023973.312,2.69845891952515,1999.896171875,39.8725471496582,0.12622452378273
1023993.296,2.69842700958252,1999.8898828125,42.8579216003418,0.129989456534386
1024013.015,2.69826042175293,1999.89180664063,45.8499450683594,0.134980486035347
1024033.187,2.69845364570618,1999.8768359375,48.841968536377,0.13808828830719
1024052.953,2.69871200561523,1999.88114257813,51.8339920043945,0.141432655453682
1024072.671,2.69873556137085,1999.88650390625,54.8260154724121,0.143091136813164
1024092.578,2.69865797042847,1999.87293945312,57.8180389404297,0.144297027587891
1024112.578,2.69873396873474,1999.89423828125,60.8100624084473,0.144798030853271
1024132.328,2.69889039993286,1999.886484375,63.7954368591309,0.145450860857964
1024152.718,2.69878798484802,1999.89956054687,66.7874603271484,0.145655869245529
1024172.984,2.6988046836853,1999.88845703125,69.7794876098633,0.145685493946075
1024192.984,2.69859459877014,1999.89955078125,72.7715148925781,0.14546506524086
1024213.156,2.69881752967834,1999.89955078125,75.763542175293,0.145251121520996
1024233.078,2.6989834690094,1999.87587890625,78.7555694580078,0.144602420926094
1024252.921,2.69911054611206,1999.89568847656,81.7475967407227,0.144352259635925
1024272.703,2.69880512237549,1999.88454101563,84.7329711914063,0.144283117055893
1024292.984,2.69882858276367,1999.87244140625,87.7249984741211,0.14394756257534
1024312.812,2.69898101806641,1999.88018554688,90.7170257568359,0.143706710338593
1024333.593,2.69881376266479,1999.87727539063,93.7090530395508,0.143755627274513
1024353.5,2.69900910377502,1999.89083007813,96.7010803222656,0.143881097435951
1024373.312,2.69896150588989,1999.89857421875,99.6931076049805,0.144489161968231
1024393.437,2.6989003944397,1999.90292480469,102.685134887695,0.144637061953545
1024413.234,2.69911640167236,1999.89277832031,105.670509338379,0.144882220029831
1024433.109,2.69912626266479,1999.89666015625,108.662536621094,0.14527748465538
1024453,2.69915733337402,1999.90826660156,111.654563903809,0.145666490793228
1024473.171,2.69911171913147,1999.91648925781,114.646591186523,0.146153510212898
1024493.015,2.69922926902771,1999.91355957031,117.638618469238,0.146572972536087
1024513.187,2.69933941841125,2000.05794433594,120.630645751953,0.146634337902069
1024534.656,2.69945468902588,2000.00321289063,123.622673034668,0.146678028106689
1024554.468,2.69922855377197,1999.91262695313,126.608047485352,0.146764043569565
1024574.406,2.69950232505798,2000.17410644531,129.600082397461,0.147013477683067
1024595.062,2.69931453704834,1999.72238769531,132.59211730957,0.146320316791534
1024614.843,2.69900014877319,1999.72622558594,135.58415222168,0.144738439321518
1024635.046,2.69933476448059,1999.73494628906,138.576187133789,0.142670201659203
1024654.812,2.69954635620117,1999.72381347656,141.568222045898,0.139670290350914
1024675,2.69945177078247,1999.72916503906,144.553604125977,0.137733093500137
1024694.812,2.6995383644104,1999.71608398438,147.545639038086,0.136631064414978
1024714.828,2.6995251750946,1999.71751953125,150.537673950195,0.135076417922974
1024734.531,2.69949927330017,1999.72769042969,153.529708862305,0.134840360879898
1024754.406,2.69958333969116,1999.73739257813,156.521743774414,0.135920052528381
1024774.312,2.69941928863525,1999.88650390625,159.513778686523,0.137114273309708
1024794.093,2.69946552276611,1999.87921875,162.505813598633,0.138430736660957
1024813.906,2.6995207118988,1999.87630859375,165.491195678711,0.14035725235939
1024833.765,2.69936940193176,1999.86760742187,168.48323059082,0.142817451953888
1024853.718,2.69961487770081,1999.86810546875,171.47526550293,0.145496767759323
1024873.625,2.69981275558472,1999.8773046875,174.467300415039,0.146482957005501
1024893.468,2.69945479393005,1999.87970703125,177.459335327148,0.146349264979362
1024913.281,2.69970311164856,1999.88262695313,180.451370239258,0.146379179954529
1024933.515,2.69982011795044,1999.87583984375,183.443405151367,0.145584058761597
1024953.718,2.69981100082397,1999.88552734375,186.428787231445,0.144945136904717
1024973.796,2.69971179008484,1999.8947265625,189.420822143555,0.143541340827942
1024993.578,2.69981911659241,1999.89905273437,192.412857055664,0.142123376131058
1025013.312,2.69998687744141,1999.89471679687,195.404891967773,0.139701924324036
1025033.546,2.69971030235291,1999.89568359375,198.396926879883,0.137606323957443
1025053.718,2.69966410636902,1999.89859375,201.388961791992,0.133334032893181
1025073.718,2.69986721992493,1999.8903515625,204.380996704102,0.128056055903435
1025093.437,2.69972933769226,1999.891796875,207.36637878418,0.124642577469349
1025113.187,2.69973246574402,1999.88166015625,210.358413696289,0.120394046902657
1025132.921,2.6995883846283,1999.89568359375,213.350448608398,0.118920834362507
1025152.718,2.69987143516541,1999.9140625,216.342483520508,0.1212190335989
1025173.093,2.69974422454834,1999.881171875,219.334518432617,0.123650651574135
1025192.906,2.69996845245361,1999.88842773438,222.326553344727,0.125961981117725
1025212.828,2.69983829498291,1999.8927734375,225.318588256836,0.131664475798607
1025233.078,2.69981944084167,1999.88891601563,228.303970336914,0.136112520694733
1025252.796,2.69980211257935,1999.89087402344,231.296005249023,0.13923604786396
1025273.203,2.70002069473267,1999.98480957031,234.288040161133,0.141971787214279
1025293.765,2.70000221252441,1999.8830859375,237.280075073242,0.14300953567028
1025313.593,2.70009565353394,1999.9024609375,240.272109985352,0.144259527921677
1025333.437,2.70027861595154,1999.87825195313,243.264144897461,0.144120321273804
1025353.75,2.70006976127625,1999.87489257812,246.25617980957,0.144717689156532
1025374.062,2.69999248504639,1999.89422851562,249.241561889648,0.144682494997978
1025393.906,2.70008857727051,1999.88986328125,252.233596801758,0.144890356659889
1025414.046,2.69960938453674,1999.871484375,255.225631713867,0.144821190834045
1025433.906,2.70001178741455,2000.17748535156,258.217681884766,0.144775597453117
1025454.078,2.69991251945496,1999.91646972656,261.209716796875,0.144879316091537
1025473.765,2.69978548049927,1999.88986816406,264.201751708984,0.144720153808594
1025493.562,2.69966390609741,1999.89712890625,267.193786621094,0.144351512789726
1025513.875,2.69998712539673,1999.91164550781,270.179168701172,0.144194279909134
1025533.906,2.69982526779175,1999.89956054687,273.171203613281,0.143900709748268
1025553.734,2.70016674041748,1999.89423828125,276.163238525391,0.144061168432236
1025573.937,2.69989639282227,1999.88163085938,279.1552734375,0.144697005748749
1025594.171,2.69996286392212,1999.91069824219,282.147308349609,0.144862473607063
1025614.484,2.70024602890015,1999.91407226563,285.139343261719,0.145652020573616
1025634.203,2.70023234367371,1999.91261230469,288.131378173828,0.14589038848877
1025654.078,2.70002109527588,1999.91067871094,291.116760253906,0.146435365080833
1025674.296,2.69989864349365,1999.90004882812,294.108795166016,0.146318376064301
1025694.296,2.70046020507812,1999.91598632813,297.100830078125,0.14666818022728
1025714.234,2.6996935749054,1999.88747070313,300.092864990234,0.147084913253784
1025734.437,2.69981495857239,1999.89857421875,303.084899902344,0.147177133560181
1025754.281,2.70004234313965,1999.90970214844,306.076934814453,0.147251876592636
1025774.375,2.69967391014099,1999.91987792969,309.068969726563,0.147255239486694
1025795.421,2.70021577835083,1999.8777734375,312.054351806641,0.147080520391464
1025815.218,2.70070471763611,1999.88795898438,315.04638671875,0.146329267024994
1025835.156,2.70033052444458,1999.89325195312,318.038421630859,0.144146268963814
1025855.171,2.7001665687561,1999.90438476563,321.030456542969,0.141889857053757
1025875.046,2.70040076255798,1999.90001953125,324.022491455078,0.139229264259338
1025894.984,2.70005265235901,1999.89181640625,327.014526367188,0.137526156306267
1025914.796,2.7003232383728,1999.90391601563,330.006561279297,0.135905433297157
1026337.515,2.89939728736877,1999.8608203125,-5.00665283203125,0.149770673513412
1026357.484,2.89892589569092,1999.90682617188,-2.00798320770264,0.149503638148308
1026377.109,2.8988756275177,1999.90582519531,0.984037637710571,0.149668343067169
1026398.015,2.89897624969482,1999.91454101563,3.97605848312378,0.149473033547401
1026418,2.89905900001526,1999.92422851562,6.96807956695557,0.149743826985359
1026437.718,2.89900296211243,1999.88840820313,9.96010112762451,0.149582079052925
1026457.468,2.89906690597534,1999.89665527344,12.9521226882935,0.149818038344383
1026477.375,2.89906024932861,1999.90631835938,15.9441442489624,0.149491322040558
1026497.171,2.89908978462219,1999.90825683594,18.9295177459717,0.149596707820892
1026517.609,2.89916561126709,1999.90051757812,21.9215393066406,0.149563995599747
1026537.468,2.89911652565002,1999.91745117188,24.9135608673096,0.148998109698296
1026557.171,2.89914800643921,1999.89424804688,27.9055824279785,0.148470532298088
1026577.281,2.89934262275696,1999.90436035156,30.8976039886475,0.147274484634399
1026597.296,2.89934259414673,1999.87779296875,33.8896255493164,0.147885238528252
1026617.187,2.899211769104,1999.72913085937,36.881649017334,0.148692097663879
1026637.218,2.89926886558533,1999.72865722656,39.8670234680176,0.149364573955536
1026657.093,2.89924196243286,1999.72770019531,42.8590469360352,0.149453452825546
1026677.453,2.8994132900238,1999.73447265625,45.8510704040527,0.149528947472572
1026697.39,2.89940053939819,1999.73593261719,48.8430938720703,0.149544416666031
1026718.062,2.89946286201477,1999.7470703125,51.8351173400879,0.149468998908997
1026737.906,2.89948758125305,1999.72865722656,54.8271408081055,0.149684242606163
1026757.812,2.89941069602966,1999.74221191406,57.8125152587891,0.149790615439415
1026778.515,2.89938270568848,1999.75190917969,60.8045387268066,0.149893475174904
1026798.734,2.89939214706421,1999.73641113281,63.7965621948242,0.149702824354172
1026818.64,2.89944456100464,1999.7315625,66.7885894775391,0.149619160890579
1026838.578,2.89946815490723,1999.74270996094,69.7806167602539,0.149672251939774
1026858.359,2.89944355010986,1999.75333496094,72.7726440429688,0.149673025012016
1026878.359,2.89960696220398,1999.73736328125,75.7646713256836,0.149616138935089
1026898.734,2.89946455001831,1999.74365722656,78.7500457763672,0.149774693250656
1026918.687,2.8993453502655,1999.75236816406,81.742073059082,0.149395434856415
1026938.703,2.89970226287842,1999.739296875,84.7341003417969,0.149688484072685
1026959.468,2.89957845687866,1999.73350585938,87.7261276245117,0.149358289241791
1026979.453,2.89955283164978,1999.75237304687,90.7181549072266,0.149410216808319
1026999.343,2.89956508636475,1999.74753417969,93.7101821899414,0.149219459891319
1027019.062,2.89956056594849,1999.7383203125,96.7022094726563,0.149292147755623
1027038.875,2.89955148696899,1999.74317382813,99.6875839233398,0.149382951259613
1027058.828,2.89975877761841,1999.75237792969,102.679611206055,0.149612503647804
1027078.781,2.89976583480835,1999.73930664063,105.67163848877,0.149495584964752
1027098.968,2.89976376533508,1999.73736816406,108.663665771484,0.149412093162537
1027118.953,2.89973050117493,1999.74605957031,111.655693054199,0.14963643848896
1027139.578,2.89982455253601,1999.75237304687,114.647720336914,0.149389539957047
1027159.75,2.89980882644653,1999.74077148438,117.639747619629,0.149559054970741
1027179.296,2.89953318595886,1999.73445800781,120.625122070313,0.149608610272408
1027199.296,2.8997251701355,1999.733515625,123.617149353027,0.149624438881874
1027219.25,2.89973823547363,1999.7455859375,126.609176635742,0.149477527737617
1027238.906,2.8998478603363,1999.72868652344,129.601211547852,0.149385804533958
1027258.546,2.89977149009705,1999.73301269531,132.593246459961,0.149316608905792
1027278.656,2.89974160194397,1999.74319335938,135.58528137207,0.149470185637474
1027298.828,2.89971597671509,1999.75961914063,138.57731628418,0.149346166849136
1027318.5,2.89970141410828,1999.74557617188,141.562698364258,0.14947449028492
1027339.109,2.89992324829102,1999.74897460938,144.554733276367,0.149359177350998
1027359.062,2.89981738090515,1999.7601171875,147.546768188477,0.149097833037376
1027378.921,2.89972825050354,1999.74412597656,150.538803100586,0.149110135436058
1027398.765,2.89987687110901,1999.74317382813,153.530838012695,0.148891295194626
1027418.593,2.89981760978699,1999.74704589844,156.522872924805,0.149158401489258
1027438.765,2.89980592727661,1999.73688964844,159.514907836914,0.149262798428535
1027458.562,2.89995205879211,1999.7407421875,162.500289916992,0.149685971736908
1027478.406,2.89991502761841,1999.74947753906,165.492324829102,0.149204711914063
1027498.687,2.89993057250977,1999.74849609375,168.484359741211,0.149415723085403
1027519.062,2.89985199928284,1999.753828125,171.47639465332,0.149711195230484
1027539.359,2.90002056121826,1999.723828125,174.46842956543,0.149563483595848
1027559.671,2.89978103637695,1999.70154785156,177.460464477539,0.149484868049622
1027579.375,2.90007639884949,1999.71221679688,180.452499389648,0.14994550049305
1027599.687,2.90011258125305,1999.84245117187,183.437881469727,0.14973171889782
1027619.546,2.90004544258118,1999.87682617188,186.429916381836,0.14994664311409
1027639.312,2.90010446548462,1999.90537109375,189.421951293945,0.149861857295036
1027659.562,2.89969267845154,1999.85063476563,192.413986206055,0.149742311835289
1027679.546,2.89959620475769,1999.85114257813,195.406021118164,0.14975004196167
1027699.312,2.8995973777771,1999.91841796875,198.398056030273,0.149598604440689
1027719.156,2.89943244934082,1999.90631835938,201.390090942383,0.149828678965569
1027738.718,2.90028340339661,1999.91553222656,204.375473022461,0.14944929599762
1027758.593,2.89961853027344,1999.92181640625,207.36750793457,0.149041187167168
1027778.281,2.89951455116272,1999.91356445313,210.35954284668,0.148203396201134
1027798.468,2.89960233688354,1999.92809082031,213.351577758789,0.14740362405777
1027818.125,2.89696959495544,1999.91838378906,216.343612670898,0.147632411122322
1027837.968,2.89903644561768,1999.90294433594,219.335647583008,0.149101803302765
1027858.265,2.89964462280273,1999.91358886719,222.327682495117,0.149122819900513
1027878.218,2.89945987701416,1999.90729492188,225.313064575195,0.149581443667412
1027898.453,2.89838591575623,1999.88747070313,228.305099487305,0.149553959369659
1027918.687,2.89952352523804,1999.89473632813,231.297134399414,0.149775047898293
1027938.421,2.89868515014648,1999.90438476563,234.289169311523,0.149727553129196
1027958.718,2.90024199485779,1999.87051757812,237.281204223633,0.149900696277618
1027979,2.89978204727173,1999.85211914063,240.273239135742,0.149764241576195
1027999.453,2.89979830741882,1999.906796875,243.265274047852,0.149738140106201
1028019.125,2.89980855941772,1999.91793945313,246.25065612793,0.149637870788574
1028039.375,2.89978832244873,1999.90197265625,249.242691040039,0.149636924266815
1028059.406,2.89987591743469,1999.89811523437,252.234725952148,0.149556156396866
1028079.328,2.90002599716187,1999.92910644531,255.226760864258,0.149617763161659
1028098.921,2.9000254535675,1999.90970214844,258.218811035156,0.149578840732574
1028118.921,2.89955490112305,1999.90534179688,261.210845947266,0.149480565786362
1028138.687,2.88677556991577,1999.88889648438,264.202880859375,0.149476788640022
1028158.562,2.89723559379578,1999.90389648438,267.188262939453,0.149437685608864
1028178.39,2.89915367126465,1999.89326171875,270.180297851563,0.149397053718567
1028198.031,2.89897253990173,1999.89422851562,273.172332763672,0.149234368801117
1028217.828,2.89929579734802,1999.92323730469,276.164367675781,0.149279795885086
1028237.812,2.90274395942688,1999.90970703125,279.156402587891,0.149429846405983
1028257.453,2.89974864006042,1999.92276367187,282.1484375,0.149334110617638
1028277.265,2.89990314483643,1999.91456054688,285.140472412109,0.149719879627228
1028297.406,2.89975890159607,1999.90391601563,288.125854492188,0.149411553740501
1028317.609,2.89968951225281,1999.89713867187,291.117889404297,0.149471664428711
1028337.921,2.89958742141724,1999.89713867187,294.109924316406,0.149516648054123
1028358.078,2.89974826812744,1999.89955078125,297.101959228516,0.14963700056076
1028378.296,2.90013210296631,1999.91502441406,300.093994140625,0.149390595555305
1028398.125,2.90002908706665,1999.91551757813,303.086029052734,0.149474403858185
1028418.234,2.8997984790802,1999.89325195312,306.078063964844,0.149489239454269
1028438.046,2.90033623695374,1999.89278808594,309.063446044922,0.149480411410332
1028458.093,2.9004158782959,1999.92423339844,312.055480957031,0.14944256901741
1028478.359,2.89274129867554,1999.90583984375,315.047515869141,0.149498842358589
1028498.156,2.89839405059814,1999.90151367187,318.03955078125,0.149267055988312
1028517.921,2.89921886444092,1999.87485351563,321.031585693359,0.149316921234131
1028537.609,2.89879128456116,1999.89181640625,324.023620605469,0.149201491475105
1028557.921,2.90537652015686,1999.89372070312,327.009002685547,0.149325374364853
1028577.703,2.90095327377319,1999.89760742187,330.001037597656,0.148930114507675
1029000.859,3.09831548690796,1999.92860351562,-5.00555419921875,0.149674449563026
1029020.671,3.09909965515137,1999.89422851562,-2.00688457489014,0.149714692831039
1029040.437,3.09909249305725,1999.87391601562,0.985136270523071,0.149656031131744
1029060.359,3.09900452613831,1999.90440429688,3.97715711593628,0.149860318303108
1029080.343,3.0990344619751,1999.90826660156,6.96917819976807,0.149638764858246
1029100.171,3.09900088310242,1999.90970703125,9.96119976043701,0.149562697410584
1029119.984,3.09915920257568,1999.90775390625,12.946572303772,0.150013593435287
1029139.5,3.09912654876709,1999.91986328125,15.9385938644409,0.149813403487206
1029159.343,3.09903395652771,1999.91889648438,18.9306163787842,0.14969881772995
1029179.671,3.0991951084137,1999.92178710937,21.9226379394531,0.149781740903854
1029199.937,3.09939526557922,1999.92037597656,24.9146595001221,0.149816222786903
1029219.625,3.09930734634399,1999.91600585938,27.906681060791,0.149886366128922
1029239.453,3.0992312335968,1999.911171875,30.89870262146,0.149920158982277
1029259.375,3.09924938201904,1999.93389160156,33.8840751647949,0.149819108843803
1029280.171,3.09918674468994,1999.94069824219,36.8760986328125,0.149845030903816
1029299.609,3.09923915863037,1999.9494140625,39.8681221008301,0.149956037998199
1029319.765,3.0994252872467,1999.92760253906,42.8601455688477,0.149862953424454
1029339.89,3.09951064109802,1999.92327636719,45.8521690368652,0.149815887212753
1029359.843,3.09941243171692,1999.93683105469,48.8441925048828,0.149804668426514
1029379.812,3.09939723014832,1999.9440625,51.8362159729004,0.149996892809868
1029399.953,3.09955308914185,1999.91357421875,54.821590423584,0.1497407579422
1029419.921,3.09570000648499,1999.94163085938,57.8136138916016,0.149928179979324
1029440.718,3.09847907066345,1999.92276855469,60.8056373596191,0.149626039862633
1029461,3.09909893035889,1999.93245605469,63.7976608276367,0.149753178358078
1029480.796,3.0996760559082,1999.92905761719,66.7896881103516,0.150022186040878
1029501.14,3.10556738853455,1999.94358886719,69.7817153930664,0.149574563503265
1029520.921,3.10000042915344,1999.94696777344,72.7737426757813,0.149706865549088
1029541.64,3.09946357727051,1999.93731445313,75.7591171264648,0.149727120995522
1029561.718,3.09948384284973,1999.92520996094,78.7511444091797,0.149760535359383
1029581.734,3.0993751335144,1999.9285546875,81.7431716918945,0.149871034026146
1029601.656,3.09933168411255,1999.92956542969,84.7351989746094,0.150201210975647
1029621.468,3.0995818901062,1999.92567871094,87.7272262573242,0.149895925521851
1029641.109,3.09937623023987,1999.92325683594,90.7192535400391,0.149863122701645
1029661.078,3.09946291923523,1999.92761230469,93.7112808227539,0.149701681137085
1029681.078,3.09958039283752,1999.91698730469,96.6966552734375,0.150053160786629
1029700.906,3.09969326019287,1999.91165527344,99.6886825561523,0.149943306446075
1029720.671,3.09955764770508,1999.91263671875,102.680709838867,0.149957678318024
1029740.406,3.09964000701904,1999.91985839844,105.672737121582,0.150019245743752
1029760.437,3.09954399108887,1999.91888183594,108.664764404297,0.150076751708984
1029780.218,3.09945239067078,1999.91599121094,111.656791687012,0.14995255112648
1029800.078,3.09963729858398,2000.18186523438,114.648818969727,0.149886892437935
1029820.515,3.09959056854248,1999.93393066406,117.63419342041,0.149739646911621
1029840.484,3.0995246219635,1999.73981933594,120.626220703125,0.149665143489838
1029860.296,3.09963496208191,1999.74077148438,123.61824798584,0.149964866042137
1029880.562,3.09967044830322,1999.73350097656,126.610275268555,0.149950624704361
1029900.453,3.09982602119446,1999.74514648438,129.602310180664,0.149852213263512
1029921.031,3.0941655254364,1999.75189941406,132.594345092773,0.150065547823906
1029941.484,3.09938928604126,1999.72527832031,135.586380004883,0.149958104491234
1029961.734,3.09909170150757,1999.73203613281,138.571762084961,0.149896007180214
1029981.625,3.10024663925171,1999.73738769531,141.56379699707,0.149853047132492
1030001.562,3.10731640815735,1999.73399902344,144.55583190918,0.149718177318573
1030021.375,3.10050828933716,1999.73978027344,147.547866821289,0.149796292185783
1030041.687,3.09985940933228,1999.74705078125,150.539901733398,0.149862852096558
1030061.859,3.09964148521423,1999.74029296875,153.531936645508,0.149839887022972
1030082.093,3.09991397857666,1999.7519140625,156.523971557617,0.149716569185257
1030102.171,3.09973683357239,1999.74462890625,159.509353637695,0.149976501464844
1030122.484,3.09979464530945,1999.763984375,162.501388549805,0.150090913772583
1030142.375,3.09971405982971,1999.73011230469,165.493423461914,0.149917361736298
1030162.25,3.09968247413635,1999.74657714844,168.485458374023,0.149996666908264
1030182.031,3.09977087020874,1999.75090820312,171.477493286133,0.149873216152191
1030202.531,3.09954792976379,1999.74026855469,174.469528198242,0.149859390854836
1030222.39,3.09987009048462,1999.7523828125,177.461563110352,0.149836620688438
1030242.14,3.09982320785522,1999.76932617188,180.44694519043,0.149931989908218
1030262.218,3.09996563911438,2000.22055175781,183.438980102539,0.150159085988998
1030282.031,3.10006014823914,1999.7509375,186.431015014648,0.149928788542747
1030302.25,3.09987833976746,1999.74076171875,189.423049926758,0.150080617070198
1030322.437,3.09980732917786,1999.76158203125,192.415084838867,0.149983317255974
1030342.171,3.10021019935608,1999.73639160156,195.407119750977,0.149977294802666
1030362.437,3.09985331535339,1999.75141601563,198.399154663086,0.149902880787849
1030382.75,3.09990297317505,1999.7508984375,201.384536743164,0.149784976243973
1030402.531,3.10002017974853,1999.754296875,204.376571655273,0.15008458673954
1030422.343,3.09786606788635,1999.72287109375,207.368606567383,0.149828770756721
1030442.546,3.09974581718445,1999.74706054688,210.360641479492,0.150078996419907
1030462.593,3.09949571609497,1999.74852050781,213.352676391602,0.150178691148758
1030482.39,3.0994550037384,1999.74899414063,216.344711303711,0.149867134094238
1030502.656,3.09993594169617,1999.74170898438,219.33674621582,0.150069486498833
1030522.859,3.09963644981384,1999.75576171875,222.322128295898,0.149903813004494
1030542.765,3.09975829124451,1999.7504296875,225.314163208008,0.149839942455292
1030562.968,3.09980151176453,1999.74897949219,228.306198120117,0.149946517348289
1030582.765,3.0999572467804,1999.72864746094,231.298233032227,0.149995608329773
1030602.718,3.09992164611816,1999.753828125,234.290267944336,0.150163640975952
1030623.031,3.09969481468201,1999.74946289063,237.282302856445,0.149956813454628
1030643.14,3.09950366020203,1999.7625390625,240.274337768555,0.149687938094139
1030663.046,3.09957279205322,1999.76157226563,243.259719848633,0.150022825598717
1030684,3.09964889526367,1999.76788085938,246.251754760742,0.149927996993065
1030703.828,3.09963389396667,1999.75138671875,249.243789672852,0.149913349151611
1030723.656,3.09987499237061,1999.75092285156,252.235824584961,0.149785645604134
1030743.406,3.09950394630432,1999.75043945313,255.22785949707,0.149968708157539
1030763.375,3.09957637786865,1999.73784667969,258.219909667969,0.150025990009308
1030783.14,3.09992840766907,1999.74561035156,261.211944580078,0.149825079441071
1030803.39,3.09966553688049,1999.75915039063,264.197326660156,0.150035685896873
1030823.25,3.09977342605591,1999.75479492187,267.189361572266,0.14983138024807
1030843.39,3.09957220077515,1999.74944824219,270.181396484375,0.149790154695511
1030863.171,3.09971632957458,1999.75526367187,273.173431396484,0.149891746044159
1030883.343,3.09972946166992,1999.75865234375,276.165466308594,0.14975254535675
1030903.187,3.09105083465576,1999.72673339844,279.157501220703,0.149705464243889
1030923.906,3.09676100730896,1999.75673828125,282.142883300781,0.149854981899261
1030944.281,3.09929675102234,1999.75721679687,285.134918212891,0.149920151233673
1030963.968,3.09944407463074,1999.75431640625,288.126953125,0.149922840595245
1030983.812,3.10751222610474,1999.95716796875,291.118988037109,0.149946464896202
1031003.921,3.10100386619568,1999.76596679688,294.111022949219,0.149829376339912
1031023.89,3.09989369392395,1999.758671875,297.103057861328,0.149887688755989
1031043.593,3.10010834693909,1999.75091796875,300.095092773438,0.149886173605919
1031064.75,3.0996771812439,1999.73448242188,303.080474853516,0.149772533774376
1031084.656,3.09961235046387,1999.73252929688,306.072509765625,0.149887657761574
1031104.343,3.09967618942261,1999.73979492188,309.064544677734,0.149904514551163
1031124.656,3.0995897769928,1999.73443847656,312.056579589844,0.149731178283691
1031145.375,3.09924925804138,1999.7509375,315.048614501953,0.149830338954926
1031165.203,3.09975130081177,1999.73497070313,318.040649414063,0.149976298809052
1031186.437,3.09958653450012,1999.75190917969,321.032684326172,0.149950070381165
1031206.562,3.09975801467896,1999.74509277344,324.01806640625,0.149967146515846
1031226.25,3.09930464744568,1999.75526367187,327.010101318359,0.149822397828102
1031245.812,3.09912047386169,1999.74705566406,330.002136230469,0.149675315618515